Workbook

Sheet 한눈에 보기
A1: 세이브타임 한눈에 보기 — 환자 한 명이 병원에 도착하기까지
A2: 처음 보는 팀원은 이 탭 → 시나리오 페이지(PM이 공유한 링크) → 03_기능요구사항에서 자기 담당 분류 순서로 보면 돼요.
A28: 8단계 요약
A29: 단계 | B29: 누가 | C29: 무엇을 | D29: 관련 요구사항
A30: 0 근무 시작 | B30: 대원 · 병원 | C30: 대원은 로그인 후 코드·QR 또는 관할 소방서 대원 목록 초대로 팀 맺기(최대 4명, 운전 1명) / 병원은 라이선스 키로 등록한 PC에서 담당자 이름 입력 후 '알림 켜기' | D30: SFR-018, 113, 159, 116, 117
A31: 1 환자 정보 입력 | B31: 처치 대원 | C31: 첫 화면에서 주 증상·성별·나이·의식·활력징후·통증·외상 입력 (측정 불가는 '확인 불가'), 운전 대원은 주행 중 입력 잠금 | D31: SFR-107, 108, 114, 115
A32: 2 병원에 요청 | B32: 대원 → 서버 | C32: 반경 안에서 알림을 켠 병원 전체에 동시 전송, 도착 예상 시간은 추정 후 길찾기로 갱신 | D32: SFR-109, 129, 012
A33: 3 병원 판단 | B33: 병원 담당자 | C33: 요청 목록 → 상세: 환자 정보 + 우리 병원 병상 + 이상 수치 빨간색 (앱은 판정 안 함) | D33: SFR-135, 118, 137
A34: 4 병원 응답 | B34: 병원 → 대원 | C34: 승인(메모)·거절(사유 7개) 즉시 전달, 첫 승인 때 대원 폰 진동, 승인 병원은 온 순서대로(가장 가까움 표시), 응답 제한 2분 · 승인 5분 유효 | D34: SFR-119, 110, 130, 127
A35: 5 병원 선택 | B35: 대원 → 서버 | C35: 승인 병원 1곳 선택 → 서버가 승인 재확인 → 확정, 나머지 병원 요청 닫고 환자 정보 열람 차단 | D35: SFR-111, 134, 125, SER-014
A36: 6 이동 | B36: 운전 대원 · 병원 | C36: 운전 폰에서 카카오 내비 자동 시작, 정보가 바뀌면 병원 웹에 강조 표시 | D36: SFR-031, 132, 105, 121
A37: 7 도착 | B37: 대원 · 병원 | C37: 응급실 입구 30m 안·저속이면 '도착 처리할까요?' 버튼 → 대원이 누름(잊으면 병원 웹 '도착 확인') → 위치 기록 익명화 + 구급활동일지 초안 | D37: SFR-038, 080, 144, 041
A38: 예비 흐름 | B38: 대원 | C38: 2분 무승인 · 전부 거절 · 유효 승인 0곳 · 5분 미선택 · 요청 대상 0곳 · 통신 두절 → 추천 5곳 → 전화 확인 → 경로 안내 | D38: SFR-112, 098, 032, 074

Sheet 00_표지
A1: 구급대원용 앱 — 요구사항분석서
A2: 세이브타임(가명) — 실시간 응급실 수용 기반 이송 지원 서비스
A4: 문서 정보
A5: 프로젝트 | B5: 세이브타임(가명) / 구급대원용 앱
A6: 문서 버전 | B6: v1.4.2
A7: 작성자 | B7: 백강욱
A8: 검토자 | B8: 최진아, 윤승언
A9: 상태 | B9: 확정 — v1.0 베이스라인 (이후 변경은 09_변경요청(CR)으로만)
A11: 버전 이력
A12: 버전 | B12: 날짜 | C12: 작성자 | D12: 변경 내용
A13: v0.9 | B13: 2026-09-26 | C13: 백강욱 | D13: 미결 15건·충돌 3건 반영, SFR 공공 SW 형식 ID로 전환, 1-6 분리, 시트로 이관
A14: v0.91 | B14: 2026-09-26 | C14: 백강욱 | D14: 신규 SFR 17건(관리자 기능 신설), 수정 23건, 중복 1건 삭제, 비기능 12건 추가, TMAP SDK 내장 확정(D-16), C-04~10 정리, 미결 D-17~19 등록
A15: v0.92 | B15: 2026-09-26 | C15: 백강욱 | D15: 계층별 점검 반영(신규 SFR 12건·비기능 14건: 이송 건 상태, 데이터 보관, 보안, 가용성 등), 개요·유스케이스 2건·우선순위표·제약사항 탭 신설, 목표 스프린트 열 추가, 구현 방법·모호어·주어 문장 정리, 문서 구조를 개요→용어→FR→NFR→제약→UC→우선순위 순으로 재배치
A16: v0.93 | B16: 2026-09-26 | C16: 백강욱 | D16: 미결 D-17(갱신 3분)·D-18(반경 20km)·D-19(이동시간 10곳) 확정, 관련 SFR·PER-003 문구 반영
A17: v0.94 | B17: 2026-09-26 | C17: 백강욱 | D17: 인수 기준 76건 작성(Must 35·Should 31·Could 10), 에러 처리 기능은 정상·예외 시나리오 함께 작성 → 인수 기준 미작성 0건
A18: v0.95 | B18: 2026-09-26 | C18: 백강욱 | D18: 06_유스케이스에 그림 3장 추가: 그림 1 유스케이스 다이어그램(전체 기능), 그림 2 UC-01 흐름도, 그림 3 UC-02 흐름도
A19: v0.96 | B19: 2026-09-26 | C19: 백강욱 | D19: 독립 검토 반영: Must 선행 10건 Must 승격·스프린트 재배치, 선행 요구사항 열, 추천 산출 순서·통신 두절 중 기록·관리자 알림 등 신규 4건, 이송 건 상태 전이표·매핑표 초안(10_부록), 결정 D-21~26, 충돌 C-12~18, 인수 기준·모호값 수정
A20: v0.97 | B20: 2026-09-26 | C20: 백강욱 | D20: 요구사항 5건 추가: 시연·테스트용 모의 모드(SFR-102), 환자 연령 구분(103), 진행 중 이송 건 1개 제한(104, Must), 이동 중 KTAS 변경(105), 관리자 통계 화면(106) / 상태 전이표 2줄 추가
A21: v0.98 | B21: 2026-09-29 | C21: 백강욱 | D21: 9/29 팀 회의 반영: 병원 요청·승인 흐름(환자 정보 첫 화면, 반경 안 동시 요청, 병원 승인·거절, 2분 제한, 대원 선택, 예비 흐름), 병원 웹·병원 계정 발급, 팀 맺기·공동 입력, KTAS 선택 입력 — 신규 SFR 20건(107~126) / 재난 지역 기능 11건 삭제, 일반인 앱 공유 백엔드 삭제 / 요구사항 분류를 한글 화면 기준으로 바꾸고 화면 ID 추가 / 유스케이스·그림·상태 전이표 새 흐름으로 교체 / 결정 D-27~42
A22: v0.99 | B22: 2026-09-29 | C22: 백강욱 | D22: 미결 결정 반영: 지도·경로 안내를 카카오로 변경(D-26, D-16 번복), 이상 수치 강조(D-38, 10_부록 E), 입력 배치 순서(D-39), 성별·나이대 추가·'확인 불가' 허용(D-40), Must 6건 Should로(D-41), 예비 추천 이동시간순(D-42)
A23: v0.100 | B23: 2026-09-29 | C23: 백강욱 | D23: 전체 검토 반영: 신규 6건(승인 유효시간·병원 승인 취소·요청용 도착 예상 시간·대원 알림·반경 넓혀 다시 요청·운전 단말 경로 안내), 미접속 병원·통신 두절 요청·팀 단위 이송·증상 미선택 게이트 규칙, 취소·수동 도착·반경·모의 모드 Must 승격, SFR-046 삭제, 고지 문구·옛 흐름 문구 정리, 상태 전이표 재작성, 결정 D-43~53 확정·D-54~55 대기
... A36: 구분 | B36: 개수 | C36: 백강욱 | D36: COR-015 확정: iOS 빌드는 팀 보유 맥, Apple 개발자 계정은 PM 생성
A37: 기능 요구사항 (삭제 제외) | B37: =COUNTA(03_기능요구사항!A2:A500)-COUNTIF(03_기능요구사항!N2:N500,"삭제") | C37: 백강욱 | D37: 개발 파트 분담 반영(D-99): 03 탭 담당 칸을 '서버 담당 / 화면 담당'으로 채움, 01_개요 1.5 역할 분담(40:30:30), 07 탭 7.3 담당별 요구사항 수 자동 집계, 04 탭 확인 담당 이름 지정
A38: Must | B38: =COUNTIFS(03_기능요구사항!H2:H500,"Must",03_기능요구사항!N2:N500,"<>삭제") | C38: 백강욱 | D38: 담당자 이름 확정: 앱 진아, 웹 승언 (팀원2·팀원3 대체)
A39: Should | B39: =COUNTIFS(03_기능요구사항!H2:H500,"Should",03_기능요구사항!N2:N500,"<>삭제") | C39: 백강욱 | D39: v0.116 (2026-10-09): 비기능 요구사항 50건 전부 확정 — 04 탭 상태를 확정으로, 목표값의 (초안) 표시 삭제
A40: Could | B40: =COUNTIFS(03_기능요구사항!H2:H500,"Could",03_기능요구사항!N2:N500,"<>삭제") | C40: 백강욱 | D40: v1.0 (2026-10-10): 베이스라인 확정 — 기능 요구사항 121건 확정, 개발 기간 1주 스프린트 × 8회(8주)로 변경(COR-001·07 스프린트 계획·용어), S8 = 통합·부하 테스트·시연 리허설, 검토자 지정, 병원 응답 2분 정책 현행 유지(D-100~103)
A41: Won't (삭제 제외) | B41: =COUNTIFS(03_기능요구사항!H2:H500,"Won't",03_기능요구사항!N2:N500,"<>삭제") | C41: 백강욱 | D41: v1.1 (2026-10-10): CR-001 승인 — 위치정보 동의 필수, 동의 거부 시 주소 입력 사용 삭제(SFR-041·092), 주소 입력은 GPS 실패 시에만(SFR-009)
A42: 삭제 처리 | B42: =COUNTIF(03_기능요구사항!N2:N500,"삭제") | C42: 백강욱 | D42: v1.2 (2026-10-12): CR-002 승인 — 운영 범위 전국 확대. 병상 수집 전국 17개 시·도(ASM-05·PER-003·SFR-023, D-59 번복 → D-104), SFR-090 복원, 동시 사용자 50명 → 동시 연결 5,000개(PER-005) + 신규 PER-007·008·QUR-012·COR-016·ASM-12, 서버 2대 구성(D-105), 길찾기 절감·상태 점검 외부(SFR-121·129·INR-002·QUR-009, D-106)
A43: v0.112 수정 (기능) | B43: =COUNTIF(03_기능요구사항!Q2:Q500,"*v0.112 수정*") | C43: 백강욱 | D43: v1.3 (2026-10-12): CR-003 승인 — v1.2 검증 반영(D-107). 정지 계정 요청마다 확인(SER-016), 시간 판정 DB 시각 통일(SFR-160), 서버 장애 뒤 재연결 병원 재전송(SFR-161·부록 A-2), 이동 중 도착 시간 SDK 전용(SFR-121·INR-002), SFR-090 S1·S5 분리, SFR-089 문구, 중복 정리(SFR-025 삭제·024·081/064·제외 병원 086 참조)
A44: Must 중 인수 기준 미작성 | B44: =COUNTIFS(03_기능요구사항!H2:H500,"Must",03_기능요구사항!G2:G500,"",03_기능요구사항!N2:N500,"<>삭제") | C44: 백강욱 | D44: v1.3 일정 (2026-10-12): 스프린트 재분배(D-108) — 병원 측 준비 4건 S3→S2, Should 4건 S6→S7, S1 서버 2대 기반·S7 2번째 서버·S8 부하·장애 테스트
A45: 전체 인수 기준 미작성 (삭제·Won't 제외) | B45: =COUNTIFS(03_기능요구사항!A2:A500,"<>",03_기능요구사항!G2:G500,"",03_기능요구사항!N2:N500,"<>삭제",03_기능요구사항!H2:H500,"<>Won't") | C45: 백강욱 | D45: v1.3 담당 (2026-10-12): D-109 — 승언에게 S1 신청·확인 3건, 통계 집계, 개인정보 자동 파기, 부하 테스트 작성·실행 이관
A46: 비기능 요구사항 | B46: =COUNTA(04_비기능요구사항!A2:A500) | C46: 백강욱 | D46: v1.4 (2026-10-25): CR-004 승인 — 10/25 교수님·구급대원 피드백 반영(D-110~123). 근무 단위 로그인·앱 잠금 삭제, 구급활동일지 초안·내보내기·음성·AI(SFR-164~167), 위치 익명 경로 축적(DAR-014), 병원 웹 덮개 알림, 거절 사유 일지 분류·축적, 만료 알림 30·7·1일(SFR-168), 병원 등급 선택(SFR-162·163, 부록 F), 관리자 독립 서버, 기능 토글·정합성 점검(QUR-013·014), 부록 G 일지 대응표
A47: 제약사항 | B47: =COUNTA(05_제약사항!A3:A18) | C47: 백강욱 | D47: v1.4.1 (2026-10-26): CR-005 승인 — v1.4 점검 반영(충돌 6·불일치 4). SER-012 일지 단말 입력 예외, SFR-037 익명화 문구, 종료(도착·취소) 후 10분 연결 기억(SFR-086·DAR-013), SER-007 이송 중 14시간, 개인 폰만(ASM-10, D-124), 만료 배너 SFR-168 일원화, 용어·등급 유지(SFR-077·128), 일지 거리 빈칸, 음성 온디바이스 우선
A48: 유스케이스 | B48: 2 | C48: 백강욱 | D48: v1.4.2 (2026-10-27): CR-006 승인 — AI 일지 정리 Could로(D-125), iOS 무음 모드 안내 SFR-092 명시, 만료 배너 규칙 명확화·SFR-146 중복 삭제(D-126), 카카오 내비 SDK 승인 반영, 정리(SFR-150 참조 제거, SFR-113 근거, DAR-014·제약 7건 확정, 파란색 규칙 삭제)
A49: 미결 결정 | B49: =COUNTIF(08_결정로그!H2:H500,"미결")
A50: 추가검증 결정 (인터뷰 확인 필요) | B50: =COUNTIF(08_결정로그!H2:H500,"추가검증")
A52: 사용 규칙
A53: 1 | B53: 한 행 = 한 요구사항. 데이터 탭(03·04·08·09)에서는 셀 병합 금지
A54: 2 | B54: ID는 절대 재사용하지 않는다. 없애는 요구사항은 지우지 말고 상태를 '삭제'로 바꾼다
A55: 3 | B55: 수정 의견은 셀 댓글 + @담당자 멘션으로 남긴다 (직접 수정 금지)
...

Sheet 01_개요
A1: 1. 개요
A3: 1.1 목적
A4: 목적 | B4: 구급대원이 현장에서 입력한 환자 정보를 반경 안 응급실에 한 번에 보내고, 승인한 병원 중 한 곳을 골라 앱 안에서 바로 경로 안내를 받을 수 있도록 지원한다. 승인이 없으면 추천 목록과 전화 확인으로 이어간다.
A5: 기대 효과 | B5: 단순 거리순 검색으로 인한 병원 거절·재이송(이른바 '응급실 뺑뺑이')을 줄여 이송 결정 시간을 단축한다.
A7: 1.2 배경
A8: 문제 | B8: 기존 거리순 검색은 현재 수용 가능한 병원을 알려주지 못해, 구급대원이 병원마다 전화를 돌리며 골든타임을 잃는다.
A9: 근거 자료 | B9: 공공 응급의료 데이터(병상·중증질환 수용), 창업 지원서 차별점, 9/29 팀 회의(구급대원 현장 평가 방식·차량당 인원), 구급대원 인터뷰(검증 예정 항목은 08_결정로그 참고)
A10: 서비스 구조 | B10: 구급대원 앱(React Native) + 병원 웹 + 관리자 웹(같은 Next.js 프로젝트) + 전용 백엔드로 구성한다. 일반인 앱은 다른 팀이 별도로 진행한다 (COR-005, 008).
A11: 구급대원 앱의 차별점 | B11: 반경 안 병원 동시 요청·병원 승인 후 출발, 병원 웹 알람, 팀 단위 공동 입력, 승인 없을 때 추천·전화 확인 예비 흐름, 통신 두절 대응
A13: 1.3 범위
A14: 포함 | B14: 환자 정보 입력, 병원 요청·응답, 팀, 병원 웹, 계정/로그인, 병상 연동·추천(예비), 경로 안내·전화 확인, 위치 기록·도착 감지, 거절 데이터 축적, 오프라인 대응, 관리자 기능
A15: 제외 | B15: 자체 지도·교통정보(ITS) 연동(D-07), 재난 지역 기능 전체(D-34), 일반인 앱(D-35), 실측 보정 예상시간(SFR-042), 병원 내부 전산 연동, 소방청 인사 정보 연동(실제 신분 인증), 사설 구급차(COR-011), 설치형 병원 프로그램·PWA(D-72), 병원 웹에 구급차 실시간 위치 표시(D-71)
A17: 1.4 대상 사용자
A18: 구급대원 | B18: 119 구급대 소속. 소속 코드 + 공무원증 사진을 관리자가 확인해 승인한 뒤 사용 (주 사용자, D-73)
A19: 병원 응급실 담당자 | B19: 관리자가 발급한 라이선스 키로 등록한 병원 PC에서 병원 웹을 사용. 이송 요청을 받아 승인·거절 (주 사용자, D-33, D-70)
A20: 관리자 | B20: 초기 데이터로 만든 관리자 계정(OTP 로그인). 가입 승인, 대원 계정 정지, 병원 계정·라이선스 키·등록 PC·응급실 입구 좌표 관리, 알림·통계 확인 (보조 사용자, D-75)
A22: 1.5 팀 구성 및 역할
A23: 전체 인원 | B23: 구급대원 서비스 3명 (일반인 앱 팀은 별도 진행)
A24: 역할 분담 (D-99) | B24: 기능 단위로 세로로 나눠 각자 자기 기능의 서버 API와 화면을 끝까지 맡는다. 비율 40 : 30 : 30 (PM 업무 포함). 03 탭 '담당' 칸 = 서버 담당 / 화면 담당
A25: 백강욱 (PM) · 40% | B25: 이송 핵심·인프라·보안: 이송·병원 정보 API, 추천 로직, 실시간 서버·재연결 모듈, 2분·5분 타이머·상태 전이, 푸시(FCM·APNs), 로그인·토큰·보안, 공공 데이터 수집기, DB·배포·CI, 공통 코드
A26: 진아 · 30% | B26: 대원 앱: 구급대원 앱 화면 21장(Android → iOS), 카카오 지도·내비 SDK 네이티브 연결, iOS 빌드 + 팀 API·계정 일부(푸시 토큰·탈퇴) 서버
A27: 승언 · 30% | B27: 병원·관리자: 병원 웹 5장·관리자 웹 4장 + 병원 웹 API·관리자 API 서버
A28: 개발 생산성 | B28: AI 개발 도구를 활용해 일반 학부 팀 대비 개발 속도를 확보하며, 이를 근거로 Must 요구사항 범위를 설정했다 (ASM-06).
A30: 1.6 개발 단계
A31: 1단계 (MVP) | B31: 환자 정보 입력 → 반경 안 병원 동시 요청 → 병원 승인 → 대원 선택 → 앱 내 경로 안내 / 승인 없으면 게이트·이동시간순 추천 → 전화 확인 (S1~S7)
A32: 2단계 (고도화) | B32: 축적된 수용·거절 데이터와 증상별 병상 가중치를 반영한 스코어링 (개발 기간 이후)
A34: 1.7 문서 규칙
A35: ID 체계 | B35: 공공 SW 사업 요구사항 분류 체계를 따른다: SFR(기능), PER(성능), QUR(품질·가용성·사용성), SER(보안), DAR(데이터), INR(인터페이스), COR(제약)
A36: 문장 형식 | B36: '시스템은 ~해야 한다' 형식으로 쓰고, 구현 방법은 제약사항(05)과 설계서에서 다룬다.
A37: 우선순위 | B37: MoSCoW(Must/Should/Could/Won't). 요구사항별 목표 스프린트(S1~S8, 1주 단위)를 함께 표기한다.

Sheet 02_용어정의
A1: 용어 | B1: 정의
A2: KTAS | B2: 한국형 응급환자 분류도구. 1~5단계, 1단계가 가장 위급. 이수자만 쓸 수 있어 선택 입력(SFR-069, D-31)
A3: 현장 평가 | B3: 구급대원이 현장에서 확인하는 환자 상태: 주 증상, 의식 수준, 활력징후(혈압·맥박·호흡수·산소포화도), 통증 부위·정도, 증상 시작 시간, 외상 여부·원인, 성별·추정 나이대 / 선택: 과거력·체온·혈당·KTAS. 주 증상은 증상 버튼(S01~S16) 중심 (SFR-108)
A4: 이송 요청 | B4: 환자 정보를 반경 안 요청 대상 병원 전체(병원 등급을 골랐으면 그 등급 이상)에 동시에 보내 수용 여부를 묻는 것. 병원 응답 제한 2분 (SFR-109, D-29)
A5: 요청 대상 병원 | B5: 검색 반경 안에 있고, 병원 웹이 서버에 연결되어 '알림 켜기'가 되어 있으며 '잠시 요청 중지' 상태가 아니며, 대원이 병원 등급을 골랐으면 그 등급 이상인 병원 (D-43, SFR-139)
A6: 승인 | B6: 병원이 '지금 받을 수 있다'는 의사를 표시한 것. 병상을 보장하지 않으며 요청 시각부터 5분만 유효하고, 병원이 '승인 취소'할 수 있다 (D-44)
A7: 예비 흐름 | B7: 병원 승인으로 이송할 수 없을 때(2분 무승인·전부 거절·유효 승인 0곳·5분 미선택·'기다리지 않고 예비로'·요청 대상 0곳·통신 두절) 추천 목록 + 전화 확인으로 병원을 찾는 흐름 (SFR-109, 112, 127)
A8: 확인 불가 | B8: 현장에서 측정하거나 물어볼 수 없는 필수 항목에 고르는 값 (예: 무의식 환자의 통증 정도). 골라도 요청을 보낼 수 있다 (D-40)
A9: 이상 수치 강조 | B9: 병원 웹에서 정상 범위를 벗어난 값(활력징후·의식·통증·체온·혈당 등)을 빨간색으로 표시하는 것. 기준: 10_부록 E (D-38)
A10: 팀 | B10: 구급차 1대에 탄 대원(최대 4명, 운전 역할 최대 1명). 차량이 2대면 팀도 2개이고 환자도 각자. 근무 시작 때 코드·QR(S2)이나 같은 관할 소방서 대원 목록 초대·수락(S5~)으로 맺고, 근무 종료·로그아웃하면 본인만 빠지며 마지막 1명이 빠지면 해제 (SFR-113, 159, D-61, D-64, D-85)
A11: 라이선스 키 | B11: 관리자가 병원마다 발급하는 키(유효 1년). 병원 PC에서 한 번 입력하면 그 PC가 병원 PC로 등록되어(최대 3대) 아이디·비밀번호 없이 병원 웹을 쓴다 (SFR-116, 123, D-70)
A12: 도착 버튼 | B12: 응급실 입구 30m 안(GPS 오차 감안)에서 시속 10km 이하가 되면 뜨는 '도착 처리할까요?' 버튼. 자동 도착은 없고 대원이 누른다 (SFR-038, D-68)
... A33: 익명 이송 경로 | B33: 이송 종료 후 위치 기록에서 대원·팀·이송 건 연결을 끊고 남긴 경로 데이터. 구급차 경로 안내 개선 연구용 (SFR-041, DAR-014)

Sheet 03_기능요구사항
A1: ID | B1: 요구사항 분류 | C1: 유형 | D1: 화면 ID | E1: 요구사항명 | F1: 상세 설명 | G1: 인수 기준 | H1: 우선순위 | I1: 개발 단계 | J1: 목표 스프린트 | K1: 출처 | L1: 근거 | M1: 담당 (서버 / 화면) | N1: 상태 | O1: 관련 결정 | P1: 최종 수정일 | Q1: 비고 | R1: 선행 요구사항
A2: SFR-041 | B2: 첫 실행·권한 | C2: 기능 | D2: S-01 | E2: 위치정보 고지·필수 동의·익명화 | F2: 시스템은 이동 종료(도착 또는 취소) 시 원본 위치 기록에서 대원 계정·팀·이송 건 연결을 즉시 끊어 '익명 이송 경로'(목적 병원ID·출발·도착 시각·좌표 열·이동 거리)로 바꿔 보관하고(DAR-014, 위치 기록이 없으면 만들지 않음), 이송 건 기록에는 이동 거리만 남겨야 한다(구급활동일지 초안, SFR-164). 첫 실행 시 수집 목적(이송 요청·도착 예상 시간 계산, 구급활동일지 거리 기록, 구급차 경로 안내 개선을 위한 익명 경로 축적)·보관 항목·보관기간과 함께 ① 환자 평가 정보와 위치로 계산한 도착 예상 시간이 요청 대상 병원에 제공된다는 것 ② 경로 안내·이동시간 산출을 위해 위치가 길찾기 서비스(카카오모빌리티)에 전달된다는 것을 동의 화면으로 고지해야 한다. 위치정보 수집은 이송 요청·도착 예상 시간 계산에 반드시 필요하므로 필수 동의이며, 고지 화면에 그 이유를 적는다. 대원이 동의하지 않으면 '위치 동의가 있어야 사용할 수 있어요' 안내와 다시 동의하기 버튼만 보여주고 다른 기능은 막는다. 동의 화면에는 주소 입력을 안내하지 않는다. 동의 후 GPS로 위치를 가져오지 못하는 경우(터널·지하 등)는 환자 정보 입력 화면의 주소 입력 버튼(SFR-009)으로 계속 사용한다. | G2: Given 앱을 처음 설치함 When 앱을 처음 실행한다 Then 수집 목적·보관 항목·보관 기간·병원 제공 항목·길찾기 서비스 전달과 필수 동의인 이유가 적힌 동의 화면이 표시된다 Given (위치정보 동의) A병원 이송 중 위치 기록 120건이 쌓여 있음 When 도착 처리가 된다 Then 위치 기록 120건이 익명 이송 경로 1건으로 바뀌어 보관되고 And 대원 계정·팀과 연결된 위치 기록은 0건이 되며 And 이송 건 기록에 이동 거리(km)가 남는다 Given (위치정보 동의) A병원 이송 중 위치 기록 60건이 쌓여 있음 When '이송 취소'를 누른다 Then 위치 기록 60건이 익명 이송 경로(취소 표시)로 바뀌고 대원 계정·팀과 연결된 위치 기록은 0건이 된다 Given 첫 실행 동의 화면 When 위치정보 수집에 '동의 안 함'을 누른다 Then '위치 동의가 있어야 사용할 수 있어요' 안내와 다시 동의하기 버튼만 표시되고 환자 정보 입력·요청은 할 수 없다 | H2: Must | I2: 1단계 | J2: S5 | K2: REQ-031,032 | L2: 개인정보보호(위치정보) 대응 | M2: 백강욱 / 진아 | N2: 확정 | O2: D-06, C-01, D-95, D-113 | P2: 2026-10-26 | Q2: [v0.96 수정] 취소 종료 시에도 원본 삭제 명시(상태 전이표) / [v0.100 수정] 고지 문구를 새 흐름에 맞게 ('제3자 제공 없음' 삭제) / [v0.108 수정] 익명 저장 검증은 SFR-039로 (C-15, 검토) / [v0.109 수정] SFR-078(동의 거부 처리) 통합, 이름 변경 / [v1.1 수정] 위치 동의 필수로 변경, 동의 거부 시 주소 입력 사용 삭제 (CR-001) / [v1.4 수정] 종료 시 삭제 → 익명 이송 경로로 축적(향후 구급차 경로 안내 개발·일지 거리), 고지 목적 추가 (CR-004, D-113) / [v1.4.1 수정] 출발 전 취소 등 위치 없으면 익명 경로 안 만듦 (CR-005) | R2: SFR-009
A3: SFR-092 | B3: 첫 실행·권한 | C3: 기능 | D3: S-01 | E3: 권한 요청 흐름 | F3: 첫 실행 시, 시스템은 위치 → 전화 → 알림 순서로 권한을 요청하고(iOS는 전화 권한이 없어 위치 → 알림), 권한마다 필요한 이유를 한 문장으로 표시해야 한다. 위치 권한은 필수이므로, 거부하면 '위치 권한이 있어야 사용할 수 있어요' 안내와 설정으로 이동 버튼을 보여주고 허용할 때까지 다음 단계로 넘어가지 않는다(SFR-041). 알림 권한을 거부하면 '병원 승인을 소리·진동으로만 알 수 있어요'를 안내한다. (알림: SFR-130) iOS에서는 알림 권한 이유 문장에 '무음 모드에서는 소리 없이 진동으로만 알려요'를 함께 표시한다. 위치는 '앱 사용 중 허용'만 요청하고 백그라운드 위치 권한은 요청하지 않는다(SFR-079). 카메라 권한은 첫 실행 때 묻지 않고 공무원증 촬영(SFR-017)·QR 스캔(SFR-113) 때 요청한다. | G3: Given Android 폰에서 앱을 처음 실행함 When 권한 요청 단계로 넘어간다 Then 위치 → 전화 → 알림 순서로 권한 요청이 표시된다 And 각 요청 앞에 필요한 이유 한 문장이 표시된다 Given 위치 권한 요청 화면 When '거부'를 누른다 Then '위치 권한이 있어야 사용할 수 있어요' 안내와 설정으로 이동 버튼이 표시되고 다음 권한 요청으로 넘어가지 않는다 Given 알림 권한 요청 화면 When '거부'를 누른다 Then '병원 승인을 소리·진동으로만 알 수 있어요' 안내가 표시되고 다음 단계로 넘어간다 Given iPhone에서 앱을 처음 실행함 When 권한 요청 단계로 넘어간다 Then 위치 → 알림 순서로만 표시되고 전화 권한 요청은 없다 Given iPhone에서 앱을 처음 실행함 When 알림 권한 요청 단계로 넘어간다 Then 알림 권한 이유 문장에 '무음 모드에서는 소리 없이 진동으로만 알려요'가 함께 표시된다 | H3: Must | I3: 1단계 | J3: S2 | K3: REQ-001,008,021 | L3: 권한 거부로 핵심 기능이 막히는 상황 최소화 | M3: - / 진아 | N3: 확정 | O3: D-73, D-97 | P3: 2026-10-27 | Q3: [v0.92 신규] / [v0.96 수정] Should→Must (Must 요구사항의 선행, C-15) / [v0.94] 인수 기준 추가 / [v0.105 수정] 알림 권한 추가 (D-63) / [v0.107 수정] 카메라 권한 시점 (D-73) / [v0.108 수정] 백그라운드 위치 권한 제거, 위치 거부해도 나머지 권한 계속 (검토) / [v0.111 수정] iOS 권한 순서(위치 → 알림) (D-97) / [v1.1 수정] 위치 권한 거부 시 진행 막음 (CR-001) / [v1.4.2 수정] iOS 무음 모드 안내 명시 — SFR-130 참조와 맞춤 (CR-006)
A4: SFR-142 | B4: 첫 실행·권한 | C4: 기능 | D4: S-01 | E4: 앱 최소 버전 확인 | F4: 앱을 실행하면, 시스템은 서버가 정한 최소 지원 버전과 앱 버전을 비교해, 더 낮으면 기능을 막고 업데이트 안내만 표시해야 한다. | G4: Given 최소 지원 버전 1.3, 설치된 앱 1.2 When 앱을 실행한다 Then '업데이트가 필요해요' 안내와 업데이트 버튼만 표시된다 | H4: Could | I4: 1단계 | J4: S7 | K4: REQ-001,008,021 | L4: 서버가 바뀐 뒤 옛 버전 앱의 오작동 방지 | M4: 진아 / 진아 | N4: 확정 | O4: D-63 | P4: 2026-09-26 | Q4: [v0.105 신규] 추가 요구사항
A5: SFR-078 | B5: 첫 실행·권한 | C5: 에러처리 | D5: S-01 | E5: 위치정보 동의 거부 처리 | F5: 만약 대원이 위치정보 수집에 동의하지 않으면, 시스템은 주소 직접 입력(SFR-009)으로 받은 위치를 기준으로 병원 조회와 이송 요청을 허용하고, 위치 기록·도착 버튼 표시(SFR-038)는 사용하지 않아야 한다. 경로 안내는 외부 내비 앱으로 넘기고(COR-003), 주행 중 운전자 입력 잠금(SFR-115)은 적용하지 않는다. 이때 도착은 메뉴의 '도착'(SFR-080)으로 처리하며, 병원 웹 '도착 확인'을 누르면 대원 앱에 도착 처리 요청이 뜬다(SFR-144). | G5: Given 첫 실행 동의 화면 When 위치정보 수집에 '동의 안 함'을 누른다 Then 주소 입력 화면이 표시되고, 입력한 주소 기준으로 병원 조회와 이송 요청을 할 수 있다 Given 위치정보에 동의하지 않은 상태에서 B병원을 선택해 이송을 시작함 When B병원 근처에 도착한다 Then 위치 기록과 '도착 처리할까요?' 버튼이 뜨지 않고 메뉴의 '도착'으로 종료하고, 병원 웹 '도착 확인'은 대원 앱에 '도착 처리할까요?'를 띄운다 | H5: Must | I5: 1단계 | J5: - | K5: REQ-031,032 | L5: 동의 없는 위치 수집 금지 | N5: 삭제 | O5: D-68, D-94 | P5: 2026-09-26 | Q5: [v0.100 수정] 새 흐름 기준으로 문구·인수 기준 수정 / [v0.107 수정] 도착 방식 변경 반영 (D-68) / [v0.108 수정] 위치 동의 시에만 위치 기록, 외부 내비·도착 처리 방식 (D-94) / [v0.109 수정] 삭제 — SFR-041에 통합 (D-95)
A6: SFR-018 | B6: 로그인 | C6: 기능 | D6: S-02 | E6: 아이디/비밀번호 로그인 | F6: 시스템은 아이디/비밀번호 로그인을 제공하고, 로그인 상태는 근무 동안만 유지해야 한다(유지 기간: SER-007). 근무 중에는 앱을 다시 열어도 로그인을 묻지 않고, 근무 종료(직접 누름 또는 14시간 자동 종료, SFR-113) 뒤에는 다시 로그인하게 한다. 근무 중 앱 잠금(PIN·생체 인증)은 두지 않는다. (소셜 로그인 미적용, 규칙: SER-006·011) | G6: Given 승인된 계정 When 올바른 아이디·비밀번호로 로그인한다 Then 근무 시작(팀) 화면으로 이동한다 (로그아웃하면 팀에서 빠지므로 로그인 직후에는 팀이 없다) Given 같은 계정으로 비밀번호를 연속 4번 틀린 상태 When 5번째도 틀린다 Then 10분 동안 로그인이 잠기고 남은 잠금 시간이 표시된다 Given 로그인해 팀을 맺은 상태 When 앱을 종료했다가 다시 실행한다 Then 로그인 화면 없이 환자 정보 입력 화면이 열린다 Given 김도윤이 '근무 종료'를 누름 When 앱을 다시 실행한다 Then 로그인 화면이 표시된다 Given 근무 시작 후 14시간이 지나 자동으로 근무 종료됨(진행 중 이송 없음) When 앱을 실행한다 Then 로그인 화면이 표시된다 | H6: Must | I6: 1단계 | J6: S2 | K6: REQ-007,012 | L6: 구현 단순화 | M6: 백강욱 / 진아 | N6: 확정 | O6: D-94, D-95, D-110 | P6: 2026-10-25 | Q6: [v0.96 수정] Should→Must (Must 요구사항의 선행, C-15) / [v0.94] 인수 기준 추가 / [v0.103 수정] 로그인 후 이동 화면 수정 (오류 4, D-61) / [v0.109 수정] SFR-019(자동 로그인) 통합 / [v1.4 수정] 30일 자동 로그인 삭제 → 근무 동안만 로그인 유지, 앱 잠금 없음 (CR-004, D-110)
A7: SFR-070 | B7: 로그인 | C7: 기능 | D7: S-02 | E7: 로그아웃 | F7: 시스템은 로그아웃 기능을 제공해야 하며, 로그아웃 시 서버의 갱신 토큰을 폐기하고 단말의 로그인 정보를 삭제해야 한다. 근무 종료(직접·자동)는 로그아웃과 같게 처리한다. 이때 그 대원은 팀에서 빠지며, 팀의 마지막 대원이면 진행 중 이송 건을 '취소'(사유 기록)로 끝낸다(SFR-113). | G7: Given 로그인해 근무 중인 상태 When 로그아웃한다 Then 로그인 화면으로 이동한다 And 앱을 다시 실행해도 로그인 화면이 표시된다 | H7: Should | I7: 1단계 | J7: S2 | K7: REQ-007,012 | L7: 개인 폰 분실 대비 (D-124) | M7: 백강욱 / 진아 | N7: 확정 | O7: D-94, D-110 | P7: 2026-10-25 | Q7: [v0.94] 인수 기준 추가 / [v0.108 수정] 팀 이탈·진행 중 이송 처리 (검토) / [v1.4 수정] 자동 로그인 문구 삭제, 근무 종료 = 로그아웃 (CR-004, D-110)
A8: SFR-150 | B8: 로그인 | C8: 기능 | D8: S-02 | E8: 앱 잠금 (생체 인증·PIN) | F8: 앱을 5분 넘게 쓰지 않다가 다시 열면, 시스템은 생체 인증(지문·Face ID) 또는 앱 PIN(숫자 6자리)으로 본인 확인을 한 뒤 화면을 보여줘야 한다. PIN은 첫 로그인 때 정하고, 생체 인증은 폰에 등록되어 있을 때만 쓴다. 5분 안에 다시 열거나, 앱이 화면에 켜져 있거나, 팀에 진행 중 이송 건(요청 중·예비 추천·전화 확인·이동 중)이 있으면 묻지 않는다. PIN을 5번 틀리면 로그아웃(팀에서 빠짐)하고 비밀번호로 다시 로그인하게 한다. | G8: Given 앱을 6분 동안 쓰지 않음 When 앱을 다시 연다 Then 생체 인증(지문·Face ID) 또는 PIN 확인 화면이 먼저 표시된다 Given 앱을 3분 동안 쓰지 않음 When 앱을 다시 연다 Then 확인 없이 이전 화면이 열린다 Given 경로 안내 화면이 30분 동안 켜져 있음 When 화면을 계속 본다 Then 잠기지 않는다 Given PIN 확인 화면 When PIN을 5번 틀린다 Then 로그아웃되고 로그인 화면이 표시된다 Given 요청을 보내고 처치하느라 7분 동안 앱을 보지 않음 When 승인 푸시를 눌러 앱을 연다 Then 잠금 없이 바로 응답 화면이 열린다 | H8: Should | I8: 1단계 | J8: S6 | K8: 9/30 회의 | L8: 폰 분실·도난 시 환자 정보·이송 기록 노출 방지, 평소엔 1초 (D-74) | M8: 진아 / 진아 | N8: 삭제 | O8: D-74, D-86, D-97, D-110 | P8: 2026-10-25 | Q8: [v0.107 신규] 9/30 회의·PM 결정 / [v0.108 수정] 진행 중 이송이 있으면 잠그지 않음, S3 → S6 (D-86) / [v0.111 수정] 지문 → 생체 인증(지문·Face ID), 이름 변경 (D-97) / [v1.4 삭제] 앱 잠금 없음 — 폰 자체 잠금으로 충분하고 위급한 현장에서 잠금 해제 시간이 부담 (CR-004, D-110) | R8: SFR-018
A9: SFR-019 | B9: 로그인 | C9: 기능 | D9: S-02 | E9: 자동 로그인 | F9: 시스템은 로그인 세션 유지(자동 로그인)를 지원해야 한다. (유지 기간: SER-007) | G9: Given '자동 로그인'을 켜고 로그인함 When 앱을 종료했다가 다시 실행한다 Then 로그인 화면 없이 근무 시작(팀) 화면 또는 팀이 있으면 환자 정보 입력 화면이 열린다 Given 자동 로그인한 지 30일이 지남 When 앱을 실행한다 Then 로그인 화면이 표시된다 | H9: Should | I9: 1단계 | J9: - | K9: REQ-007,012 | L9: 출동 중 로그인 절차 제거 | N9: 삭제 | P9: 2026-09-26 | Q9: [v0.94] 인수 기준 추가 / [v0.103 수정] 로그인 후 이동 화면 수정 (오류 4, D-61) / [v0.104 수정] Could → Should (출동마다 로그인하지 않도록, D-62) / [v0.109 수정] 삭제 — SFR-018(로그인)에 통합 (D-95)
A10: SFR-017 | B10: 회원가입·계정 | C10: 기능 | D10: S-02 | E10: 소속 확인 가입 | F10: 시스템은 구급대원 가입 신청 때 소속기관 코드(소방서 단위), 이름·계급·소속 안전센터·사번, 공무원증 사진(촬영 또는 앨범)과 사진 수집·이용 동의를 받아야 하며, 관리자가 사진을 확인해 승인(SFR-083)해야 가입이 완료된다. 동의하지 않거나 사진이 없으면 신청할 수 없다. (사진 보호: SER-015, 보관: DAR-012) | G10: Given 등록된 소속기관 코드를 가진 대원 When 코드·이름·계급·안전센터·사번과 공무원증 사진을 올리고 동의해 신청한다 Then '승인 대기' 상태로 가입 신청이 접수된다 Given 등록되지 않은 소속기관 코드 When 가입 신청한다 Then 신청이 접수되지 않고 '소속기관 코드를 확인하세요'가 표시된다 Given 공무원증 사진을 올리지 않음 When '신청'을 누른다 Then '공무원증 사진을 올려 주세요'가 표시되고 신청되지 않는다 Given 사진 수집·이용에 동의하지 않음 When '신청'을 누른다 Then 신청되지 않고 동의 안내가 표시된다 | H10: Must | I10: 1단계 | J10: S5 | K10: REQ-007,012 | L10: 구급대원 전용 기능 보호, 개발 기간(8주) 내 구현 가능한 수준 | M10: 백강욱 / 진아 | N10: 확정 | O10: D-02, D-73 | P10: 2026-09-26 | Q10: 실제 신분 인증 연동은 향후 과제 / [v0.96 수정] Should→Must (Must 요구사항의 선행, C-15) / [v0.94] 인수 기준 추가 / [v0.107 수정] 공무원증 사진·계급·안전센터·사번 추가 (D-73)
A11: SFR-022 | B11: 회원가입·계정 | C11: 에러처리 | D11: S-02 | E11: 미인증 계정 처리 | F11: 만약 계정이 승인 전이면, 시스템은 로그인 후 '승인 대기 중' 화면만 표시하고 앱의 다른 기능은 막아야 한다. 화면에는 신청 일시와 '승인되면 알림으로 알려드려요'를 보여주고, 승인·반려 결과가 나오면 알림으로 알린다. (권한표: SER-010) | G11: Given 승인 대기 계정으로 로그인 When 앱을 실행한다 Then '승인 대기 중' 화면만 표시되고 환자 정보 입력·추천 목록·팀 화면은 열리지 않는다 Given 승인 대기 중 When 관리자가 승인한다 Then '가입이 승인됐어요' 알림이 오고 다음 실행 때 근무 시작(팀) 화면이 열린다 | H11: Should | I11: 1단계 | J11: S5 | K11: REQ-007,012 | L11: 승인 전 계정이 수집 데이터를 오염시키지 않도록 | M11: 백강욱 / 진아 | N11: 확정 | O11: D-95 | P11: 2026-09-26 | Q11: '제한된 기능' 범위 — 팀 확인 필요 / [v0.96 수정] 승인 대기 계정의 경로 안내 불가 명시(SER-010 ①과 일치) / [v0.98 수정] 이송 요청 전송도 승인 후로 / [v0.100 수정] 새 첫 화면에 맞게 조회 전용 진입점 정의 / [v0.109 수정] 조회 전용 '주변 병원 보기' 없애고 '승인 대기 중' 화면 하나로 | R11: SFR-017
A12: SFR-071 | B12: 회원가입·계정 | C12: 기능 | D12: S-02 | E12: 회원 탈퇴 | F12: 대원이 탈퇴하면, 시스템은 계정·프로필 정보를 즉시 삭제해야 한다. 익명 데이터(SFR-039, 126)는 계정과 연결되지 않으므로 유지한다. (보관: DAR-003) 이때 그 대원은 팀에서 빠지며, 팀의 마지막 대원이면 진행 중 이송 건을 '취소'(사유 기록)로 끝낸다(SFR-113). | G12: Given 대원 B 계정으로 만든 익명 소요시간 기록이 3건 있음 When 대원 B가 탈퇴한다 Then B의 계정·프로필이 즉시 삭제되어 같은 아이디로 로그인되지 않는다 And 익명 소요시간 기록 3건은 남아 있다 | H12: Should | I12: 1단계 | J12: S2 | K12: REQ-007,012 | L12: 개인정보 파기 요건 | M12: 진아 / 진아 | N12: 확정 | O12: D-94 | P12: 2026-09-26 | Q12: [v0.94] 인수 기준 추가 / [v0.108 수정] 팀 이탈·진행 중 이송 처리 (검토)
A13: SFR-020 | B13: 회원가입·계정 | C13: 기능 | D13: S-02 | E13: 프로필 소속·직급 | F13: 시스템은 프로필에 소속·직급 정보를 선택 입력으로 저장해야 한다. | G13: Given 로그인한 대원 When 소속 '천안동남소방서', 직급 '소방교'로 프로필을 저장한다 Then 프로필 화면에 입력한 소속·직급이 표시된다 Given 로그인한 대원 When 소속·직급 없이 프로필을 저장한다 Then 오류 없이 저장된다 | H13: Could | I13: 1단계 | J13: - | K13: REQ-007,012 | N13: 삭제 | P13: 2026-09-26 | Q13: [v0.94] 인수 기준 추가 / [v0.104 수정] 삭제 — 가입 때 소속 코드로 확인 (D-62)
A14: SFR-113 | B14: 팀 | C14: 기능 | D14: S-03 | E14: 팀 맺기 | F14: 시스템은 로그인한 구급대원이 근무를 시작할 때 팀을 만들거나 참여하게 해야 한다. 팀은 구급차 1대에 탄 대원(최대 4명)이며, 한 명이 팀을 만들면 4자리 코드와 QR을 표시하고 다른 대원은 코드 입력 또는 QR 스캔으로 참여한다(목록에서 초대하는 방식: SFR-159, 그 뒤로 코드·QR은 목록에 없는 대원용 예비 수단). 팀원은 각자 '운전'·'처치' 역할을 고르며 '운전'은 팀에 최대 1명이다. 참여자가 아직 없어도 팀을 만든 대원은 바로 환자 정보 입력으로 넘어갈 수 있다. '근무 종료'나 로그아웃을 하면 그 대원만 팀에서 빠지고, 마지막 1명이 빠지면 팀이 해제된다. 진행 중 이송 건이 있으면 빠지기 전에 '진행 중 이송 1건이 있어요'를 경고하고, 마지막 1명이면 이송 건을 '취소'(사유 '근무 종료')로 끝낼지 확인받는다. 승인된 계정만 팀에 참여할 수 있다. 근무 시작 후 14시간(SER-007)이 지나고 진행 중 이송이 없으면 자동으로 근무 종료(팀에서 빠짐)하고, 로그아웃(SFR-070)과 같게 처리해 다음 실행 때 로그인 화면을 보여준다. 대원이 직접 누른 근무 종료도 로그아웃과 같다. | G14: Given 김도윤이 팀을 만듦 (코드 4821) When 이하준이 코드 4821을 입력한다 Then 두 사람이 한 팀으로 표시된다 Given 팀원이 4명인 상태 When 5번째 대원이 코드를 입력한다 Then '팀 인원이 가득 찼어요(최대 4명)'가 표시되고 참여되지 않는다 Given 김도윤이 이미 '운전' 역할을 고름 When 이하준이 역할을 고른다 Then '운전'은 선택할 수 없고 '처치'만 고를 수 있다 Given 팀을 만들었지만 아직 참여한 대원이 없음 When '환자 정보 입력으로'를 누른다 Then 환자 정보 입력 화면으로 넘어간다 Given 김도윤·이하준·이서준 한 팀, 진행 중 이송 없음 When 이서준이 '근무 종료'를 누른다 Then 이서준만 팀에서 빠지고 김도윤·이하준은 그대로 한 팀이다 Given 팀에 김도윤 1명만 남았고 B병원으로 이동 중 When 김도윤이 '근무 종료'를 누른다 Then '진행 중 이송 1건이 있어요 — 취소하고 종료할까요?'가 표시된다 | H14: Must | I14: 1단계 | J14: S2 | K14: 9/29 회의 | L14: 구급차 1대당 2~3명이 함께 이송 | M14: 진아 / 진아 | N14: 확정 | O14: D-32, D-47, D-61, D-64, D-85, D-96, D-110 | P14: 2026-10-27 | Q14: [v0.98 신규] 9/29 회의 / [v0.100 수정] CPR 2대 출동 시 합류, 최대 6명 (D-47) / [v0.103 수정] 차량 1대=팀 1개, 최대 4명, 운전 1명, 근무 시작 시 필수 → Must·S2 (D-61) / [v0.107 수정] 코드·QR → 관할 소방서 대원 목록에서 초대·수락, 동명이인 구분, 코드·QR은 예비 (D-64) / [v0.108 수정] S2는 코드·QR로 맺기만, 목록 초대는 SFR-159(S5)로 분리, 근무 종료는 본인만 빠짐 (D-85, D-94) / [v0.110 수정] 개발 충돌 점검 (D-96) / [v1.4 수정] 근무 종료(직접·자동) = 로그아웃 (CR-004, D-110) / [v1.4.2 수정] 14시간 근거를 확정값 SER-007로 (CR-006) | R14: SFR-018
A15: SFR-114 | B15: 팀 | C15: 기능 | D15: S-03 | E15: 팀원 간 환자 정보 공유·공동 입력 | F15: 같은 팀에서 한 팀원이 환자 정보를 입력하면, 시스템은 다른 팀원 화면에 실시간으로 반영하고, 다른 팀원도 이어서 입력할 수 있게 해야 한다. 같은 항목을 동시에 고치면 나중에 입력한 값으로 저장하고 알린다. 팀의 작성 중 환자 정보는 서버에 1개만 두고 팀원 단말이 함께 고친다. | G15: Given 김도윤과 이하준이 한 팀 When 김도윤이 혈압 160/95를 입력한다 Then 이하준 화면에도 혈압 160/95가 바로 표시되고 And 이하준이 이어서 맥박을 입력할 수 있다 | H15: Should | I15: 1단계 | J15: S6 | K15: 9/29 회의 | L15: 처치하는 사람 대신 다른 팀원이 입력 (9/29 회의) | M15: 진아 / 진아 | N15: 확정 | O15: D-32, D-96 | P15: 2026-09-26 | Q15: [v0.98 신규] 9/29 회의 / [v0.103 수정] 팀 필수(D-61)에 맞게 문장 정리 / [v0.110 수정] 개발 충돌 점검 (D-96) | R15: SFR-113, SFR-108
A16: SFR-115 | B16: 팀 | C16: 기능 | D16: S-03 | E16: 주행 중 운전자 입력 잠금 | F16: 팀에서 '운전' 역할인 대원의 단말은 차량이 이동 중(시속 10km 이상)인 동안 입력을 잠그고 보기만 허용해야 한다. 정차하면 다시 입력할 수 있다. | G16: Given 김도윤이 '운전' 역할이고 시속 40km로 이동 중 When 환자 정보 입력란을 누른다 Then 입력되지 않고 '주행 중에는 팀원이 입력해요'가 표시된다 Given 같은 상황에서 차량이 정차함 When 입력란을 누른다 Then 입력할 수 있다 | H16: Should | I16: 1단계 | J16: S6 | K16: 9/29 회의 | L16: 운전 중 화면 조작 방지, 주행 중에는 다른 팀원이 입력 (D-37) | M16: 진아 / 진아 | N16: 확정 | O16: D-37 | P16: 2026-09-26 | Q16: [v0.98 신규] 9/29 회의 | R16: SFR-113
A17: SFR-132 | B17: 팀 | C17: 기능 | D17: S-03 | E17: 운전 역할 단말 경로 안내 자동 시작 | F17: 승인 병원이 선택되면, 시스템은 '운전' 역할 대원의 단말에서 경로 안내를 자동으로 시작하고, 다른 팀원 단말에는 목적지·남은 시간만 표시해야 한다. '운전' 역할이 없거나 운전 단말이 10초 안에 응답하지 않으면 선택한 대원의 단말에서 시작한다. 위치 기록과 도착 버튼은 경로 안내를 시작한 단말 1대에서만 동작한다. 서버가 이송 건에 '경로 안내 담당 단말'을 하나 지정하고(버전 번호와 함께, SFR-160), 늦게 응답한 운전 단말은 보기 전용으로 둔다. 앱 재실행(SFR-133) 때도 지정된 담당 단말만 위치 기록을 다시 시작한다. | G17: Given 김도윤(운전)·이하준(처치) 한 팀 When 이하준이 B병원을 선택한다 Then 김도윤 단말에서 B병원 경로 안내가 자동으로 시작되고 이하준 단말에는 'B병원 · 9분 남음'이 표시된다 Given 팀에 '운전' 역할이 없음 When 이하준이 B병원을 선택한다 Then 이하준 단말에서 경로 안내가 시작된다 Given 김도윤(운전) 폰이 꺼져 있음 When 이하준이 B병원을 선택하고 10초가 지난다 Then 이하준 단말에서 경로 안내가 시작된다 | H17: Should | I17: 1단계 | J17: S6 | K17: 9/29 회의 | L17: 운전자는 입력이 잠겨 있어 병원을 직접 고르지 않음 (D-47) | M17: 백강욱 / 진아 | N17: 확정 | O17: D-47, D-94, D-96 | P17: 2026-09-26 | Q17: [v0.100 신규] 전체 검토 반영 / [v0.103 수정] 팀 필수(D-61)에 맞게 문장 정리 / [v0.110 수정] 개발 충돌 점검 (D-96) | R17: SFR-113, SFR-031
A18: SFR-143 | B18: 팀 | C18: 기능 | D18: S-03 | E18: 팀원 메모 (나만 보기) | F18: 대원이 다른 대원에 대해 나만 보는 한 줄 메모(최대 20자, 예: '3센터 운전 담당')를 남기면, 시스템은 팀원 목록 초대(SFR-159)의 목록·검색 결과에서 그 대원 이름 아래에 메모를 작게 표시해야 한다. 메모는 쓴 대원 본인에게만 보이며, 이름 대신 표시하지 않는다. | G18: Given 김도윤이 이하준에게 메모 '3센터 운전 담당'을 남김 When 김도윤이 '목록에서 초대'를 연다 Then 이하준 이름 아래에 '3센터 운전 담당'이 작게 표시된다 Given 같은 상태 When 이서준이 '목록에서 초대'를 연다 Then 이하준 아래에 메모가 보이지 않는다 | H18: Could | I18: 1단계 | J18: S7 | K18: 9/30 회의 | L18: 자주 함께 출동하는 동료를 빨리 찾기 (9/30 회의 1-B) | M18: 진아 / 진아 | N18: 확정 | O18: D-64 | P18: 2026-09-26 | Q18: [v0.107 신규] 9/30 회의·PM 결정 | R18: SFR-159
A19: SFR-159 | B19: 팀 | C19: 기능 | D19: S-03 | E19: 팀원 목록 초대 | F19: 시스템은 팀을 만든 대원이 같은 관할 소방서 대원 목록에서 팀원을 골라 초대하게 해야 한다. 목록은 지금 근무 중(근무 시작 후 근무 종료 전, SFR-113 자동 근무 종료 포함)인 승인된 대원을 먼저 보여주고, 찾는 대원이 없으면 이름 검색으로 소방서 전체에서 찾는다. 목록에는 동명이인을 구분하도록 이름·계급·소속 안전센터·사번 뒤 4자리(가입 정보 SFR-017)를 표시한다. 초대받은 대원의 폰에 '팀 초대' 알림이 가고 '수락'해야 팀원이 된다. 초대는 5분 뒤 만료되고, 이미 다른 팀에 있는 대원은 초대할 수 없다. | G19: Given 서북소방서에서 이하준·이서준이 근무 중 When 김도윤이 '목록에서 초대'를 연다 Then 근무 중 대원 목록에 '이하준 · 소방교 · 서북119안전센터 · 1234'처럼 표시된다 Given 서북소방서에 '김민수'가 2명 있고 둘 다 근무 중이 아님 When 이름 검색에 '김민수'를 입력한다 Then 두 사람이 계급·안전센터·사번 뒤 4자리로 구분되어 표시된다 Given 김도윤이 이하준을 초대함 When 이하준이 '수락'을 누른다 Then 두 사람이 한 팀으로 표시된다 Given 김도윤이 이하준을 초대함 When 이하준이 '거절'을 누른다 Then 이하준은 팀에 들어가지 않고 김도윤 화면에 '이하준 님이 초대를 거절했어요'가 표시된다 Given 이서준이 이미 다른 팀에 있음 When 김도윤이 이서준을 초대한다 Then '이미 다른 팀에 있어요'가 표시되고 초대되지 않는다 Given 이하준이 초대에 5분 동안 응답하지 않음 When 5분이 지난다 Then 초대가 만료되고 김도윤 화면에 '초대가 만료됐어요'가 표시된다 | H19: Must | I19: 1단계 | J19: S5 | K19: 9/29 회의 | L19: 9/30 회의 1번: 코드·QR 대신 목록에서 고르기 (가입 기능과 같은 S5에 구현, D-85) | M19: 진아 / 진아 | N19: 확정 | O19: D-64, D-85 | P19: 2026-09-26 | Q19: [v0.108 신규] 전체 점검 반영 | R19: SFR-113, SFR-017, SFR-130
A20: SFR-003 | B20: 환자 정보 입력 | C20: 기능 | D20: S-04 | E20: 증상/부위 필터 | F20: 대원이 주 증상을 증상 버튼(10_부록 B, 입력은 SFR-108)으로 고른 경우, 시스템은 예비 흐름의 추천 목록을 증상→진료가능 항목 매핑표(DAR-002)에 따라 해당 항목이 '가능'인 병원만 남겨야 한다. (산출 순서: SFR-098 ④) | G20: Given 검색 반경 안 병원 8곳 중 '[뇌출혈수술] 거미막하출혈' 또는 '[뇌출혈수술] 거미막하출혈 외'가 '가능'인 병원이 3곳임 When 증상에서 'S03 갑작스러운 극심한 두통·의식 저하'를 선택한다 Then 추천 후보에 3곳만 남는다 And 나머지 5곳은 지도에만 표시된다 | H20: Should | I20: 1단계 | J20: S6 | K20: REQ-001,008,021 | L20: 증상별 수용 가능 병원만 추려야 함 | M20: 백강욱 / 진아 | N20: 확정 | P20: 2026-09-26 | Q20: [v0.96 수정] 인수 기준을 추천 산출 순서(SFR-098)와 맞춤 / [v0.98 수정] 증상 선택지는 선택 입력, 예비 추천에만 사용 / [v0.108 수정] 입력은 SFR-108, 이 요구사항은 필터만 (검토) | R20: SFR-098
A21: SFR-069 | B21: 환자 정보 입력 | C21: 기능 | D21: S-04 | E21: KTAS 선택 입력 | F21: 시스템은 환자 정보 입력 화면에서 KTAS 1~5단계를 선택 입력으로 제공해야 한다. KTAS를 선택하지 않아도 이송 요청을 보낼 수 있다. 앱은 KTAS로 위급도를 판정하지 않는다(D-38). | G21: Given KTAS를 선택하지 않은 상태 When 필수 항목을 모두 입력하고 '병원에 요청'을 누른다 Then 요청이 정상적으로 전송된다 Given KTAS 2단계를 선택함 When 병원에 요청을 보낸다 Then 병원 웹의 요청 상세에 'KTAS 2'가 표시된다 | H21: Should | I21: 1단계 | J21: S6 | K21: REQ-001,008,021 | L21: KTAS 이수 대원은 병원에 등급을 함께 전달 (D-31, 앱은 등급으로 판정하지 않음 D-38) | M21: 진아 / 진아 | N21: 확정 | O21: D-31, D-38 | P21: 2026-09-26 | Q21: [v0.92 수정] 주어 '시스템' 명시 / [v0.98 수정] KTAS 이수자만 선택 입력, 위급도 기준은 미결(D-38) / [v0.100 수정] 근거를 새 흐름 기준으로 / [v0.103 수정] 옛 문구 수정 (오류 20)
A22: SFR-103 | B22: 환자 정보 입력 | C22: 기능 | D22: S-04 | E22: 환자 연령 구분 | F22: 시스템은 현장 평가의 추정 나이대(SFR-108)가 1세 미만 또는 1~14세이면 '소아'로 보고, 예비 추천에서 매핑표(DAR-002)의 영유아 항목으로 필터링해야 한다. 나이대가 '확인 불가'이면 성인 기준을 쓴다. | G22: Given 후보 6곳 중 '[응급내시경] 성인 위장관' 가능 4곳, '[응급내시경] 영유아 위장관' 가능 2곳 When 나이대 '1~14세', 증상 S06으로 예비 추천을 연다 Then 추천 후보에 2곳만 남는다 Given 같은 후보, 나이대 '확인 불가' When 증상 S06으로 예비 추천을 연다 Then 성인 항목 기준으로 4곳이 남는다 | H22: Should | I22: 1단계 | J22: S6 | K22: REQ-001,008,021 | L22: 매핑표 S06·S07의 소아 항목 구분 근거 | M22: 진아 / 진아 | N22: 확정 | P22: 2026-09-26 | Q22: [v0.97 신규] 소아 기준(만 15세 미만)은 인터뷰 확인 / [v0.98 수정] 환자 정보 입력 화면으로 위치 변경 / [v0.99 수정] 나이대 입력으로 소아 여부 자동 결정 (D-40) | R22: SFR-108, SFR-003
A23: SFR-107 | B23: 환자 정보 입력 | C23: 기능 | D23: S-04 | E23: 환자 정보 입력 화면 (첫 화면) | F23: 팀이 맺어진 대원이 앱을 실행하면, 시스템은 환자 정보 입력 화면을 첫 화면으로 표시해야 한다. 항목은 주 증상 → 성별·나이대 → 의식·활력징후 → 통증 → 외상 → 선택 항목 순서로 배치하되 입력 순서를 강제하지 않으며, 필수 항목(SFR-108)이 모두 채워지면(값 또는 '확인 불가') '병원에 요청' 버튼을 활성화한다. | G23: Given 로그인되어 있고 팀이 맺어진 대원 When 앱을 실행한다 Then 환자 정보 입력 화면이 첫 화면으로 표시되고 맨 위에 주 증상 입력란이 있다 Given 입력 화면 When 주 증상보다 맥박을 먼저 입력한다 Then 맥박이 정상적으로 입력되고 다른 항목도 계속 입력할 수 있다 Given 필수 항목 중 맥박이 비어 있음 When 나머지 항목을 모두 입력한다 Then '병원에 요청' 버튼이 비활성 상태로 남고 '맥박을 입력하세요'가 표시된다 | H23: Must | I23: 1단계 | J23: S2 | K23: REQ-001,008,021 | L23: 현장에서 가장 먼저 하는 일이 환자 평가라서 | M23: 진아 / 진아 | N23: 확정 | O23: D-31, D-39 | P23: 2026-09-26 | Q23: [v0.98 신규] 9/29 회의 / [v0.99 수정] 화면 배치 순서·순서 비강제 (D-39) / [v0.103 수정] 팀 필수 반영 (D-61) | R23: SFR-108, SFR-113
A24: SFR-108 | B24: 환자 정보 입력 | C24: 기능 | D24: S-04 | E24: 현장 평가 입력 | F24: 시스템은 다음 항목을 입력받아야 한다. 필수: 주 증상, 성별(남/여), 추정 나이대(1세 미만·1~14세·15~19세·20대~80대·90세 이상), 의식 수준(명료/말에 반응/통증에 반응/무반응), 혈압, 맥박, 호흡수, 산소포화도, 통증 부위, 통증 정도(0~10), 증상 시작 시간, 외상 여부(있으면 원인). 주 증상은 증상 버튼(10_부록 B S01~S16)을 먼저 보여주고 버튼을 누르면 주 증상이 채워지며, 버튼에 없으면 직접 입력한다(버튼을 고르면 증상 선택지로도 쓰인다). 주 증상을 뺀 필수 항목은 '확인 불가'를 고를 수 있어야 하며, 주 증상이 채워지면 '나머지 확인 불가로 보내기' 버튼으로 비어 있는 필수 항목을 한 번에 '확인 불가'로 채울 수 있다. 선택: 과거력, 체온, 혈당, KTAS(입력란은 SFR-069에서 S6에 추가). 이름·주민번호·연락처 입력란은 두지 않는다(SER-012). | G24: Given 입력 화면 When 주 증상 버튼 'S03 갑작스러운 극심한 두통·의식 저하', 남, 60대, 의식 '말에 반응', 혈압 160/95, 맥박 88, 호흡 20, 산소포화도 96, 통증 부위 '머리', 통증 8, 시작 '30분 전', 외상 '없음'을 입력한다 Then 필수 항목이 모두 채워졌다고 표시되고 '병원에 요청' 버튼이 활성화된다 Given 의식 '무반응' 환자 When 통증 부위·정도·시작 시간을 '확인 불가'로 고르고 나머지를 입력한다 Then '병원에 요청' 버튼이 활성화되고, 병원 웹에 해당 항목이 '확인 불가'로 표시된다 Given 입력 화면 When 외상 여부를 '있음'으로 바꾼다 Then 외상 원인 선택지(교통사고·추락·넘어짐·관통상·화상·기타)가 나타나고 필수 항목이 된다 Given 주 증상만 '흉통'으로 채운 상태 When '나머지 확인 불가로 보내기'를 누른다 Then 비어 있는 필수 항목이 모두 '확인 불가'로 채워지고 '병원에 요청' 버튼이 활성화된다 Given 증상 버튼에 맞는 증상이 없음 When 주 증상을 직접 '손가락 절단'으로 입력한다 Then 주 증상이 채워지고 증상 선택지는 '미선택'으로 남는다 | H24: Must | I24: 1단계 | J24: S2 | K24: REQ-001,008,021 | L24: KTAS 미이수 대원이 많아 현장 평가 항목으로 입력 (9/29 회의) | M24: 진아 / 진아 | N24: 확정 | O24: D-31, D-40, D-83 | P24: 2026-09-26 | Q24: [v0.98 신규] 9/29 회의 / [v0.99 수정] 성별·나이대 추가, 주 증상을 뺀 필수 항목 '확인 불가' 허용 (D-40) / [v0.103 수정] 비고 문구 수정 (오류 21) / [v0.108 수정] 주 증상은 증상 버튼 중심 + '나머지 확인 불가로 보내기', KTAS·증상 선택지 소관 명확화 (D-83, 검토)
A25: SFR-109 | B25: 병원 요청·응답 | C25: 기능 | D25: S-05 | E25: 이송 요청 동시 전송 | F25: 대원이 '병원에 요청'을 누르면, 시스템은 현재 검색 반경(SFR-012) 안에 있고 병원 웹이 서버에 연결되어 '알림 켜기'가 되어 있고 '잠시 요청 중지'(SFR-139) 상태가 아니며, 대원이 병원 등급을 골랐으면(SFR-162) 그 등급 이상인 병원 전체에 환자 정보와 도착 예상 시간(SFR-129)을 동시에 전송해야 한다. 요청 대상이 0곳이거나 단말이 통신 두절 상태이면 요청을 보내지 않고 바로 '예비 추천'(SFR-112)으로 전환하며, 이송 요청은 단말에 보관했다가 나중에 보내지 않는다. 이송 건은 팀 단위로 1건만 만든다(SFR-104). | G25: Given 반경 20km 안 병원 10곳 중 병원 웹이 연결되고 알림이 켜진 병원이 8곳임 When '병원에 요청'을 누른다 Then 8곳에만 요청이 전송되고 And 대원 화면에 '8곳에 요청함 · 응답 대기 2:00'이 표시된다 Given 반경 안에 알림이 켜진 병원이 0곳 When '병원에 요청'을 누른다 Then 요청을 보내지 않고 '응답 가능한 병원이 없어요'와 함께 추천 목록으로 전환된다 Given 단말이 통신 두절 상태 When '병원에 요청'을 누른다 Then 요청이 보관되지 않고 예비 추천 화면으로 전환된다 Given 반경 20km 안 요청 가능 병원 8곳 중 대학병원급 2곳·종합병원급 3곳·일반 병원 3곳, 대원이 '종합병원급'을 고름 When '병원에 요청'을 누른다 Then 대학병원급 2곳과 종합병원급 3곳, 모두 5곳에만 요청이 전송된다 | H25: Must | I25: 1단계 | J25: S3 | K25: 9/29 회의 | L25: 전화를 한 곳씩 돌리는 시간을 없애는 핵심 기능 | M25: 백강욱 / 진아 | N25: 확정 | O25: D-28, D-43, D-45, D-120 | P25: 2026-10-25 | Q25: [v0.98 신규] 9/29 회의 / [v0.100 수정] 연결·알림 켜짐 병원만, 0곳·오프라인이면 바로 예비, 팀 단위 1건 (D-43, D-45, D-47) / [v0.103 수정] 팀 필수(D-61)에 맞게 문장 정리 / [v0.105 수정] 요청 중지 병원 제외 (D-63) / [v1.4 수정] 고른 병원 등급 이상에만 요청 (구급대원 피드백, CR-004, D-120) | R25: SFR-107, SFR-116, SFR-117, SFR-012, SFR-129
A26: SFR-110 | B26: 병원 요청·응답 | C26: 기능 | D26: S-05 | E26: 병원 응답 실시간 표시 | F26: 요청을 보낸 뒤, 시스템은 병원별 응답 상태(대기/승인/거절 + 거절 사유/승인 취소)와 남은 응답 시간을 실시간으로 표시해야 한다. 승인 병원은 승인이 온 순서대로 위에서부터 쌓고 이미 표시된 병원의 위치는 바꾸지 않으며, 각 병원에 예상 이동시간을 크게 표시하고 그중 가장 가까운 병원에 '가장 가까움'을 붙인다. 남은 시간은 서버가 내려준 남은 초로만 센다. 서버 연결이 끊긴 채 남은 시간이 0이 되고 승인한 병원이 없으면 '임시 예비'로 추천 목록을 보여주고, 다시 연결되면 서버 상태로 바꾸며 그사이 승인이 있었으면 경보(SFR-130)로 알린다. 승인한 병원이 있으면 승인 유효시간(SFR-127) 동안 선택할 수 있다. 통신이 끊긴 채 요청 후 5분이 지나면 승인 목록을 비활성화한다. | G26: Given 8곳에 요청을 보낸 상태 When C병원(14분)이 먼저, B병원(9분)이 나중에 승인하고 A병원이 거절한다 Then 승인 목록에 C병원이 위, B병원이 아래에 표시되고 순서가 바뀌지 않으며 And B병원에 '가장 가까움'이 붙고 A병원은 '거절', 나머지 5곳은 '대기'로 표시된다 Given 승인한 병원이 없는 상태에서 요청 후 1분에 통신이 끊김 When 남은 시간이 0이 된다 Then '임시 예비' 표시와 함께 추천 목록이 표시된다 Given '임시 예비' 중 서버에는 1:55에 들어온 D병원 승인이 있음 When 통신이 다시 연결된다 Then 경보와 함께 D병원 승인이 표시되고 선택할 수 있다 | H26: Must | I26: 1단계 | J26: S3 | K26: 9/29 회의 | L26: 대원이 응답을 기다리는 동안 상황을 알아야 함 | M26: 백강욱 / 진아 | N26: 확정 | O26: D-67, D-84, D-93, D-96 | P26: 2026-09-26 | Q26: [v0.98 신규] 9/29 회의 / [v0.100 수정] 앱 자체 2분 타이머 (D-45) / [v0.103 수정] 전환 조건 추가 (오류 13) / [v0.107 수정] 거절 사유 표시 (D-67) / [v0.108 수정] 승인 병원 순서 고정·'가장 가까움' 표시, 남은 시간은 서버 기준, 끊김 시 임시 예비 (D-84, D-93) / [v0.110 수정] 개발 충돌 점검 (D-96) | R26: SFR-109, SFR-119
A27: SFR-111 | B27: 병원 요청·응답 | C27: 기능 | D27: S-05 | E27: 승인 병원 선택 | F27: 승인한 병원이 1곳 이상이면, 시스템은 대원이 그중 한 곳을 고르게 하고 'B병원으로 확정할까요?'를 한 번 확인받은 뒤, 서버 확정이 끝나면 이송 건을 '이동 중'으로 바꾸고 경로 안내(SFR-031)를 시작해야 한다. 병원 선택은 단말에 보관했다가 나중에 보내지 않으며(SFR-099 제외), 5초 안에 서버 응답이 없으면 'B병원으로 출발하세요 (확정 중 — 아직 확정 아님)'을 표시하고 뒤에서 확정을 다시 시도하고, 끝내 실패하면 경보로 알린다. 확정 요청에는 같은 확정을 여러 번 보내도 한 번만 처리되는 키를 붙이고, 판정은 첫 시도가 서버에 도착한 시각으로 한다. | G27: Given B병원(9분)과 C병원(14분)이 승인한 상태 When B병원을 누르고 '확정'을 누른다 Then B병원으로 경로 안내가 시작되고 And B병원 웹의 요청에 '확정'이 표시된다 Given B병원을 누름 When 'B병원으로 확정할까요?'에서 '취소'를 누른다 Then 확정되지 않고 승인 목록으로 돌아간다 Given '확정'을 누른 순간 통신이 느려 5초 동안 서버 응답이 없음 When 5초가 지난다 Then 'B병원으로 출발하세요 (확정 중 — 아직 확정 아님)'이 표시되고 확정을 다시 시도한다 | H27: Must | I27: 1단계 | J27: S3 | K27: 9/29 회의 | L27: 먼저 승인한 곳이 더 멀 수 있어 대원이 판단 (D-30) | M27: 백강욱 / 진아 | N27: 확정 | O27: D-30, D-84, D-93, D-96 | P27: 2026-09-26 | Q27: [v0.98 신규] 9/29 회의 / [v0.103 수정] 인수 기준을 S3 기능 기준으로 (오류 15) / [v0.108 수정] '확정할까요?' 한 번 확인, 서버 확정이 늦으면 '확정 중' 표시 (D-84, D-93) / [v0.110 수정] 개발 충돌 점검 (D-96) | R27: SFR-110
A28: SFR-112 | B28: 병원 요청·응답 | C28: 기능 | D28: S-05 | E28: 무응답·전부 거절 시 예비 흐름 | F28: 요청 후 2분 안에 승인한 병원이 없거나, 모든 병원이 거절하거나, 응답 대기 병원이 없는 상태에서 유효한 승인이 승인 취소로 0곳이 되거나, 요청이 전달된 병원이 0곳이거나(SFR-161), 대원이 '기다리지 않고 예비로'를 누르면, 시스템은 남은 요청을 닫고 '예비 추천'으로 전환해 추천 목록(SFR-098)을 보여주고 전화 확인(SFR-032, S4)으로 이어지게 해야 한다. 제외 병원(SFR-086)은 추천 목록에서 뺀다. '기다리지 않고 예비로'를 누르면 승인한 병원의 요청도 닫고 병원 웹에 '요청 종료'를 표시한다. | G28: Given 8곳에 요청했고 2분 동안 승인이 없음 When 제한 시간이 끝난다 Then '승인한 병원이 없어요 · 가까운 병원에 전화로 확인하세요' 안내와 함께 추천 목록이 표시된다 Given 8곳 모두 거절함 When 마지막 거절이 도착한다 Then 2분을 기다리지 않고 바로 추천 목록으로 전환된다 Given 요청 후 40초, 응답 대기 중 When '기다리지 않고 예비로'를 누른다 Then 8곳의 요청이 닫히고 바로 추천 목록이 표시된다 Given (S4 이후) 요청 후 3분, 다른 병원은 모두 만료되었고 유일한 승인 병원 B가 '승인 취소'함 When 취소가 도착한다 Then 5분을 기다리지 않고 바로 추천 목록으로 전환되고 B병원은 목록에서 빠진다 | H28: Must | I28: 1단계 | J28: S3 | K28: 9/29 회의 | L28: 병원 응답이 없어도 이송이 멈추면 안 됨 | M28: 백강욱 / 진아 | N28: 확정 | O28: D-29, D-36, D-94, D-96 | P28: 2026-10-12 | Q28: [v0.98 신규] 9/29 회의 / [v0.100 수정] '기다리지 않고 예비로' 버튼 추가 (D-43) / [v0.108 수정] 유효 승인 0곳이 되면 바로 예비, 제외 규칙 통일 (검토) / [v0.110 수정] 개발 충돌 점검 (D-96) / [v1.3 수정] 제외 병원은 SFR-086 참조만 (CR-003) | R28: SFR-124, SFR-098
A29: SFR-130 | B29: 병원 요청·응답 | C29: 기능 | D29: S-05 | E29: 대원 알림 (진동·소리·푸시) | F29: 시스템은 첫 승인 도착, 전부 거절, 응답 시간 만료(2분), 승인 유효시간 해제 1분 전(요청 후 4분)과 해제(5분), 승인 취소, 연결 복구 후 새로 확인된 승인(SFR-110), 확정 병원의 추가 메모(SFR-140), 도착 후 수용 불가(SFR-158) 때 팀원 전원의 단말에 진동과 소리로 알려야 하며, 앱이 백그라운드이거나 화면이 꺼져 있으면 푸시 알림(COR-009)으로 알린다. (트리거별 구현 시점: 첫 승인·전부 거절·2분 만료 S3, 승인 해제 경보·승인 취소 S4, 연결 복구 승인 S3, 추가 메모 S4, 수용 불가 S7) iPhone이 무음 모드이면 소리 없이 진동으로만 알리며(폰 설정에 따름), 알림 권한 요청 화면(SFR-092)에서 이를 안내한다. 무음 모드를 무시하는 iOS '중요 알림'은 Apple 별도 승인이 필요해 쓰지 않는다. | G29: Given 요청을 보내고 앱을 백그라운드로 둔 채 처치 중 When B병원이 승인한다 Then 푸시 알림 'B병원 승인 · 9분'이 오고 단말이 진동한다 Given 팀원 3명이 같은 요청을 보는 중 When 2분이 지나 만료된다 Then 3명의 단말 모두 진동·소리로 알린다 Given (S4 이후) B병원이 승인했고 요청 후 4분이 되도록 병원을 고르지 않음 When 요청 후 4분이 된다 Then '1분 뒤 승인이 해제돼요' 경보가 울린다 Given iPhone이 무음 모드이고 앱이 백그라운드 When B병원이 승인한다 Then 소리 없이 푸시 알림과 진동이 온다 | H29: Must | I29: 1단계 | J29: S3 | K29: 9/29 회의 | L29: 대원은 처치 중이라 화면을 보고 있지 않음 (D-51) | M29: 백강욱 / 진아 | N29: 확정 | O29: D-51, D-77, D-90, D-93, D-96, D-97 | P29: 2026-09-26 | Q29: [v0.100 신규] 전체 검토 반영 / [v0.103 수정] 팀 필수(D-61)에 맞게 문장 정리 / [v0.108 수정] 만료 구분, 승인 해제 1분 전 경보, 추가 메모·연결 복구 승인 (검토, D-90, D-93) / [v0.110 수정] 개발 충돌 점검 (D-96) / [v0.111 수정] iOS 무음 모드 처리 (D-97) | R29: SFR-110
A30: SFR-131 | B30: 병원 요청·응답 | C30: 기능 | D30: S-06 | E30: 반경 넓혀 다시 요청 | F30: '예비 추천' 상태에서 대원이 '반경 넓혀 다시 요청'을 누르면, 시스템은 요청 반경을 한 단계 넓히고(최대 40km) 넓힌 반경 안 요청 대상 중 이번 이송에서 아직 요청하지 않은 병원('요청한 병원' 목록 기준, SFR-086)에만 요청을 보내 이송 건을 '요청 중'으로 되돌려야 한다. 제외 병원(SFR-086)은 빼고, 넓힐 반경이 없거나 새 대상이 0곳이면 안내 후 예비 추천에 머문다. 고른 병원 등급(SFR-162)은 그대로 유지한다. | G30: Given 반경 20km 요청이 만료되어 예비 추천 상태 When '반경 넓혀 다시 요청'을 누른다 Then 반경이 30km가 되고 20~30km 사이 대상 병원에만 새 요청이 가며 이송 건이 '요청 중'이 된다 Given 반경이 이미 40km When '반경 넓혀 다시 요청'을 확인한다 Then 버튼이 비활성화되고 '더 넓힐 수 없어요'가 표시된다 | H30: Should | I30: 1단계 | J30: S4 | K30: 9/29 회의 | L30: 예비 흐름에서도 병원 승인 기회를 한 번 더 (D-50) | M30: 백강욱 / 진아 | N30: 확정 | O30: D-50, D-96 | P30: 2026-10-25 | Q30: [v0.100 신규] 전체 검토 반영 / [v0.110 수정] 개발 충돌 점검 (D-96) / [v1.3 수정] 제외 병원은 SFR-086 참조만 (CR-003) / [v1.4 수정] 반경을 넓혀도 병원 등급 유지 (D-120) | R30: SFR-112, SFR-012
A31: SFR-149 | B31: 병원 요청·응답 | C31: 기능 | D31: S-05 | E31: 승인 병원 지도 표시 | F31: 요청 중 응답 화면에서, 시스템은 승인한 병원의 위치와 대원 현재 위치를 지도에 표시하고, 목록에서 병원을 누르면 지도에서 그 병원을 강조해야 한다. 지도를 불러오지 못하면 목록만 보여준다. | G31: Given B병원·C병원이 승인한 상태 When 응답 화면을 본다 Then 지도에 대원 위치와 B·C병원 위치가 표시된다 Given 같은 상태 When 목록에서 C병원을 누른다 Then 지도에서 C병원이 강조된다 Given 지도를 불러오지 못함 When 응답 화면을 본다 Then 지도 없이 응답 목록만 표시된다 | H31: Should | I31: 1단계 | J31: S7 | K31: 9/30 회의 | L31: 승인 병원이 여러 곳일 때 위치를 보고 고르기 (9/30 회의 8) | M31: 백강욱 / 진아 | N31: 확정 | O31: D-71 | P31: 2026-10-12 | Q31: [v0.107 신규] 9/30 회의·PM 결정 / [v1.3 일정] S6 → S7 (스프린트 재분배, D-108) | R31: SFR-110
A32: SFR-001 | B32: 추천 목록(예비) | C32: 기능 | D32: S-06 | E32: 주변 응급실 자동 로드 | F32: 팀이 맺어진 대원이 앱을 실행하면, 시스템은 환자 정보 입력 화면(SFR-107)을 먼저 표시하고, 그동안 현재 위치 기준 검색 반경 안의 응급실 목록을 미리 불러와야 한다. | G32: Given 팀이 맺어져 있고 위치 권한이 허용되어 있으며 반경 20km 안에 응급실 12곳이 있음 When 앱을 실행한다 Then 환자 정보 입력 화면이 먼저 표시된다 And 입력하는 동안 반경 안 응급실 12곳의 목록을 미리 불러와 둔다 | H32: Must | I32: 1단계 | J32: S2 | K32: REQ-001,008,021 | L32: 예비 흐름·요청 대상 판단에 쓸 병원 목록을 입력하는 동안 미리 준비 | M32: 백강욱 / 진아 | N32: 확정 | O32: C-05 | P32: 2026-09-26 | Q32: [v0.96 수정] 추천 카드(S2)와 같은 스프린트로 이동 / [v0.98 수정] 첫 화면이 환자 정보 입력으로 변경 (D-31) / [v0.100 수정] 근거를 새 흐름 기준으로 / [v0.103 수정] 팀 조건 추가 (D-61) | R32: SFR-092, SFR-027
A33: SFR-002 | B33: 추천 목록(예비) | C33: 기능 | D33: S-06 | E33: 목록 요약 정보 표시 | F33: 시스템은 추천 카드마다 병원명·거리·예상 이동시간·잔여 병상 수·중증질환 진료가능 항목 수를 요약 표시해야 한다. | G33: Given A병원(거리 3.2km, 예상 9분, 응급실 가용 4, 중증질환 진료가능 항목 3개)이 추천 후보에 있음 When 추천 목록 화면을 연다 Then A병원 카드에 병원명·3.2km·9분·잔여 병상 4·'중증질환 진료가능 3'이 모두 표시된다 | H33: Must | I33: 1단계 | J33: S2 | K33: REQ-001,008,021 | L33: 카드 한 장으로 1차 판단 가능해야 함 | M33: 백강욱 / 진아 | N33: 확정 | P33: 2026-09-26 | Q33: [v0.96 수정] '수용 가능' 표현 → '진료가능 항목'(C-16)
A34: SFR-006 | B34: 추천 목록(예비) | C34: 기능 | D34: S-06 | E34: 수동 새로고침 | F34: 대원이 새로고침 버튼을 누르면, 시스템은 즉시 최신 데이터를 다시 조회해야 한다. | G34: Given 목록이 기준 14:00 데이터로 표시 중이고, 서버에 14:03 데이터가 있음 When 새로고침 버튼을 누른다 Then 목록이 14:03 데이터로 바뀐다 And 카드의 기준 시각이 14:03으로 표시된다 | H34: Must | I34: 1단계 | J34: S2 | K34: REQ-001,008,021 | L34: 전화 직전 최신 상태 확인 | M34: 백강욱 / 진아 | N34: 확정 | P34: 2026-09-26 | Q34: 기존 1-6을 두 행으로 분리 / [v0.94] 인수 기준 추가
A35: SFR-008 | B35: 추천 목록(예비) | C35: 에러처리 | D35: S-06 | E35: 네트워크 불안정 시 데이터 유지 | F35: 만약 앱의 목록 조회 요청이 5초 안에 응답을 받지 못하거나 실패하거나, 서버의 공공 데이터 수집이 실패해 최신 데이터가 없으면, 시스템은 마지막으로 저장된 데이터를 유지하고 데이터 상태 문구표(SFR-081)의 '참고용 정보' 문구로 표시해야 한다. 저장 데이터도 없으면 빈 화면 대신 '불러올 수 있는 병원 정보가 없습니다' 안내와 새로고침 버튼을 표시한다. | G35: Given 기준 14:00 목록이 표시된 상태에서 서버가 응답하지 않음 When 새로고침 버튼을 누른다 Then 14:00 목록이 그대로 유지되고 화면이 비지 않는다 And 카드에 '참고용 정보 · 기준 14:00'이 표시된다 Given 공공 데이터 수집이 실패했고 기준 13:50 저장 데이터가 있음 When 목록을 조회한다 Then 저장 데이터가 '참고용 정보 · 기준 13:50'과 함께 표시된다 Given 공공 데이터 수집이 실패했고 저장 데이터도 없음 When 목록을 조회한다 Then '불러올 수 있는 병원 정보가 없습니다' 안내와 새로고침 버튼이 표시된다 | H35: Should | I35: 1단계 | J35: S5 | K35: REQ-001,008,021 | L35: 화면이 비는 상황 방지 | M35: 백강욱 / 진아 | N35: 확정 | O35: C-09 | P35: 2026-09-26 | Q35: [v0.96 수정] 모호어 '불안정' 정의, 자동 갱신(S6) 의존 제거 / [v0.96 수정] 앱→서버 응답 제한시간 5초로 명시 / [v0.99 수정] Must → Should (D-41) / [v0.104 수정] SFR-028(공공 데이터 실패)과 통합 (D-62)
A36: SFR-009 | B36: 추천 목록(예비) | C36: 에러처리 | D36: S-06 | E36: 위치 실패 시 주소 입력 | F36: 만약 위치 정보를 가져오지 못하면, 시스템은 환자 정보 입력 화면을 그대로 띄우고 반경 표시 옆에 '위치 확인 불가 · 주소 입력' 버튼을 보여, 주소를 입력하면 그 위치를 요청·추천 기준 위치로 써야 한다. (좌표 변환: INR-004) | G36: Given GPS 신호를 받지 못해 위치를 가져올 수 없음 When 앱을 실행한다 Then 환자 정보 입력 화면이 표시되고 반경 옆에 '위치 확인 불가 · 주소 입력' 버튼이 있다 Given '주소 입력'을 누름 When '천안시 동남구 신부동'으로 주소 검색을 한다 Then 입력한 주소가 기준 위치로 설정되고 반경 20km가 그 위치 기준으로 계산된다 Given 주소 입력 화면 When 존재하지 않는 주소로 검색한다 Then '주소를 찾을 수 없습니다'가 표시되고 입력 화면이 유지된다 | H36: Must | I36: 1단계 | J36: S2 | K36: REQ-001,008,021 | L36: GPS 실패 시에도 검색 가능해야 함 | M36: 백강욱 / 진아 | N36: 확정 | O36: D-94 | P36: 2026-10-10 | Q36: [v0.94] 인수 기준 추가 / [v0.103 수정] S4 → S2 (오류 15) / [v0.108 수정] 첫 화면은 환자 정보 입력 유지, 주소 입력은 버튼으로 (검토) / [v1.1] 주소 입력은 GPS 실패 시에만 사용 (CR-001, 문장 변경 없음)
A37: SFR-012 | B37: 추천 목록(예비) | C37: 기능 | D37: S-06 | E37: 검색 반경 설정·표시 | F37: 시스템은 환자 정보 입력 화면의 '병원에 요청' 버튼 옆과 추천 카드 영역 위에서 검색 반경을 10·20·30·40km 중 바꿀 수 있게 해야 한다(기본 20km). 이 반경은 이송 요청 대상(SFR-109)과 예비 추천 범위에 쓰인다. 요청 중(응답 대기 화면)에는 반경을 바꿀 수 없고, 넓히려면 예비 추천의 '반경 넓혀 다시 요청'(SFR-131)을 쓴다. 이송 건에는 요청 반경과 예비 추천 반경을 따로 저장한다(SFR-029는 추천 반경만 넓힌다). | G37: Given 입력 화면 '병원에 요청' 옆에 '반경 20km'가 표시됨 When 반경을 30km로 바꾸고 요청한다 Then 반경 30km 안 대상 병원에 요청이 전송된다 Given 반경 20km로 8곳에 요청 중 When 응답 대기 화면을 본다 Then 반경은 '20km'로 표시만 되고 바꿀 수 없다 | H37: Must | I37: 1단계 | J37: S3 | K37: REQ-001,008,021 | L37: 지역별 병원 밀도 차이 대응 | M37: 백강욱 / 진아 | N37: 확정 | O37: D-18, D-28, D-50, D-82, D-96 | P37: 2026-09-26 | Q37: [v0.96 수정] 설정 가능 범위 명시 / [v0.98 수정] 반경 설정을 추천 카드 영역으로 이동, 동시 전송 범위와 연결 / [v0.100 수정] Must로, 입력 화면에도 배치, 요청 중 넓히면 추가 전송 (D-50) / [v0.108 수정] 요청 중 반경 넓히기 삭제 (D-82, D-50 일부 번복) / [v0.110 수정] 개발 충돌 점검 (D-96)
A38: SFR-027 | B38: 추천 목록(예비) | C38: 기능 | D38: S-06 | E38: 추천 카드 상위 5개 표시 | F38: 예비 흐름에서, 시스템은 게이트를 통과한 후보 중 상위 5개를 추천 카드로 표시해야 한다. 반경 내 전체 병원은 지도에 표시한다. | G38: Given 게이트를 통과한 후보가 9곳이고, 반경 안 응급실이 15곳임 When 추천 목록 화면을 연다 Then 추천 카드는 5장만 표시된다 And 지도에는 응급실 마커 15개가 모두 표시된다 | H38: Must | I38: 1단계 | J38: S2 | K38: REQ-002,005,024 | L38: 이송 중 판단 부담 최소화 | M38: 백강욱 / 진아 | N38: 확정 | O38: C-05 | P38: 2026-09-26 | Q38: [v0.98 수정] 재난 문구 삭제 / [v0.100 수정] 번복된 결정 C-04 참조 삭제 / [v0.94] 인수 기준 추가 | R38: SFR-098
A39: SFR-029 | B39: 추천 목록(예비) | C39: 에러처리 | D39: S-06 | E39: 추천 0건 대체 안내 | F39: 만약 추천 후보가 0건이면(최초 조회 또는 거절로 모두 제외된 경우), 시스템은 검색 반경을 한 단계 넓혀(10→20→30→40km) 다시 조회할지 묻는 안내를 표시해야 한다. 반경이 이미 40km이면 넓히기 안내 없이 '가까운 병원에 전화로 확인하세요' 안내를 표시한다. | G39: Given 반경 20km 안에 게이트 통과 후보가 0곳임 When 추천 목록을 조회한다 Then '반경을 30km로 넓혀 다시 찾을까요?' 안내가 표시된다 Given 같은 안내가 표시된 상태 When '넓혀서 찾기'를 누른다 Then 반경 30km 기준으로 다시 조회한 결과가 표시된다 Given 반경 40km에서도 후보가 0곳 When 추천 목록을 조회한다 Then 넓히기 안내 없이 '가까운 병원에 전화로 확인하세요' 안내가 표시된다 | H39: Must | I39: 1단계 | J39: S4 | K39: REQ-002,005,024 | L39: 빈 화면 방지 | M39: 백강욱 / 진아 | N39: 확정 | P39: 2026-09-26 | Q39: [v0.92 수정] '반경 확장 등' 모호어 제거 → 2배 확장으로 구체화 / [v0.96 수정] 거절로 후보가 모두 빠진 경우 포함, 최대 반경 / [v0.96 수정] SFR-074(Must)의 선행이라 Must 승격 / [v0.94] 인수 기준 추가 / [v0.103 수정] 반경 2배(최대 80km) → 한 단계 넓힘(최대 40km) (오류 1) / [v0.103 수정] S5 → S3 (예비 흐름 전화 확인이 S3에 끝까지 동작)
A40: SFR-094 | B40: 추천 목록(예비) | C40: 기능 | D40: S-06 | E40: 지도 마커-카드 연동 | F40: 대원이 지도 마커를 누르면, 시스템은 해당 병원 카드를 강조 표시하고 목록을 그 카드 위치로 이동해야 한다. | G40: Given 추천 카드 5장이 표시되고 3번째가 B병원임 When 지도에서 B병원 마커를 누른다 Then B병원 카드가 강조 표시된다 And 목록이 B병원 카드 위치로 이동한다 | H40: Could | I40: 1단계 | J40: S7 | K40: REQ-001,008,021 | L40: 지도와 목록을 오가며 비교 | M40: 백강욱 / 진아 | N40: 확정 | P40: 2026-09-26 | Q40: [v0.92 신규] / [v0.94] 인수 기준 추가 / [v0.104 수정] Should → Could (D-62)
...

Sheet 04_비기능요구사항
A1: ID | B1: 분류 | C1: 요구사항명 | D1: 상세 설명 | E1: 목표값 | F1: 측정 방법 | G1: 관련 SFR | H1: 확인 담당 | I1: 상태 | J1: 비고
A2: PER-001 | B2: 성능 | C2: 추천 API 응답시간 | D2: 추천 목록 요청의 95%를 목표값 이내에 응답해야 한다. (이동시간 산출 포함) | E2: 3초 | F2: 부하 테스트 p95 측정 | G2: SFR-098, 072 | H2: 백강욱 | I2: 확정
A3: PER-002 | B3: 성능 | C3: 첫 화면 표시 시간 | D3: 앱 실행부터 환자 정보 입력 화면 표시까지 목표값 이내여야 한다. | E3: 3초 | F3: 실기기 10회 측정 평균 | G3: SFR-107 | H3: 백강욱 | I3: 확정 | J3: [v0.98 수정] 첫 화면이 환자 정보 입력으로 변경 (D-31) / [v0.103 수정] 이름 수정 (오류 19)
A4: PER-003 | B4: 성능 | C4: 실시간 병상 수집 주기 | D4: 시스템은 실시간 병상 데이터를 목표값 주기로 수집해야 한다. | E4: 3분 (전국 17개 시·도, D-17·D-104) | F4: 수집 로그 확인 | G4: SFR-023 | H4: 백강욱 | I4: 확정 | J4: v0.93 / [v1.2 수정] 시·도 1곳 → 전국 17개 시·도, 하루 약 8,160회 (CR-002, D-104)
A5: PER-006 | B5: 성능 | C5: 요청 → 병원 알림 시간 | D5: 대원이 '병원에 요청'을 누른 뒤 병원 웹에 알림이 뜨기까지, 병원 응답이 대원 앱에 표시되기까지 각각 목표값 이내여야 한다. 길찾기 결과로 도착 예상 시간을 갱신하는 것(SFR-129)은 별도 목표값을 따른다. | E5: 각 3초 이내, 도착 예상 시간 갱신 10초 이내 | F5: 요청 20회 측정 | G5: SFR-109, 117, 119, 129 | H5: 백강욱 | I5: 확정 | J5: [v0.98 신규] 9/29 회의
A6: PER-004 | B6: 성능 | C6: 배터리 소모 | D6: 경로 안내 + 위치 기록 1시간 동안 배터리 소모가 목표값 이하여야 한다. | E6: 15% 이하 | F6: 실기기 1시간 주행 테스트 | G6: SFR-037, 079 | H6: 백강욱 | I6: 확정
A7: PER-005 | B7: 성능 | C7: 동시 연결 | D7: 병원 웹 PC와 구급대원 앱의 실시간 연결이 목표값만큼 동시에 유지되는 상태에서도 PER-001(추천 응답)과 PER-006(요청·응답 알림)을 만족해야 한다. | E7: 5,000개 (병원 PC 약 1,230 + 대원 앱 약 3,300 + 여유) | F7: 클라우드 서버에서 부하 테스트 (S8) | G7: SFR-098, 109, 117 | H7: 승언 | I7: 확정 | J7: [v0.92 신규] 성능 목표의 기준 인원 / [v1.2 수정] 동시 사용자 50명 → 동시 연결 5,000개 (전국 운영 규모, CR-002, D-105) / [v1.3 담당] 확인 담당 백강욱 → 승언 (D-109: 부하 테스트 작성·실행, 결과 분석·튜닝은 백강욱)
A8: QUR-001 | B8: 가용성 | C8: 공공 API 장애 시 조회 | D8: 공공 데이터 장애 시에도 저장 데이터 기반 목록 조회가 가능해야 한다. (처리 순서: SFR-024) | E8: 저장 데이터 존재 시 100% | F8: API 차단 후 조회 테스트 | G8: SFR-024, 008 | H8: 백강욱 | I8: 확정 | J8: / [v0.104 수정] 관련 요구사항 통합 반영
A9: QUR-009 | B9: 가용성 | C9: 서비스 가용률 | D9: 최종 시연 2주 전부터 시연일까지 서비스 가용률이 목표값 이상이어야 한다. | E9: 99% | F9: 5분 간격 상태 점검 기록 (서버 밖 외부 점검 서비스) | G9: - | H9: 백강욱 | I9: 확정 | J9: [v0.92 신규] / [v1.2 수정] 상태 점검을 서버 밖에서 (데이터 서버가 멈추면 알림도 못 보내는 문제, D-106)
A10: QUR-010 | B10: 가용성 | C10: 백업·복구 | D10: 데이터는 1일 1회 이상 백업하고, 장애 시 목표값 이내에 복구해야 한다. | E10: 4시간 이내 | F10: 복구 리허설 1회 | G10: - | H10: 백강욱 | I10: 확정 | J10: [v0.92 신규]
A11: QUR-002 | B11: 안정성 | C11: 오프라인 핵심 기능 | D11: 통신 두절 시에도 병원 목록·카드·전화 걸기가 동작해야 한다. | E11: 3개 기능 동작 | F11: 비행기 모드 테스트 | G11: SFR-059, 061, 064, 068 | H11: 백강욱 | I11: 확정 | J11: / [v0.108 수정] 통합 반영 (D-80)
A12: QUR-003 | B12: 사용성 | C12: 경로 안내까지 조작 수 | D12: 병원 승인이 표시된 뒤 경로 안내 시작까지 목표값 이내 터치로 가능해야 한다. | E12: 2회 | F12: 시나리오 테스트 | G12: SFR-111, 031 | H12: 진아 | I12: 확정 | J12: [v0.98 수정] 새 흐름 기준
A13: QUR-004 | B13: 호환성 | C13: 지원 OS | D13: 목표값 이상 OS에서 정상 동작해야 한다. | E13: Android 10 이상 · iOS 16 이상 | F13: 실기기 테스트 (Android 1대 이상 · iPhone 1대 이상) | G13: - | H13: 진아 | I13: 확정 | J13: [v0.96 수정] 결정 D-22 / [v0.111 수정] iOS 추가 (D-97, D-22 번복)
A14: QUR-005 | B14: 사용성 | C14: 야간(다크) 모드 | D14: 시스템은 야간 구급차 안에서 눈부심이 없도록 다크 모드를 제공해야 한다. | E14: 시스템 설정 따름 + 수동 선택(라이트/다크) | F14: 야간 실사용 점검 | G14: SFR-096 | H14: 진아 | I14: 확정 | J14: [v0.96 수정] SFR-096과 일치
A15: QUR-006 | B15: 사용성 | C15: 최소 터치 영역 | D15: 전화·경로 안내 등 핵심 버튼은 장갑 낀 손으로도 누를 수 있는 크기여야 한다. | E15: 48dp 이상 | F15: UI 점검 | G15: SFR-031, 033 | H15: 진아 | I15: 확정
A16: QUR-007 | B16: 사용성 | C16: 핵심 정보 글자 크기 | D16: 병원명·병상 수·이동시간은 흔들리는 차량에서도 읽을 수 있는 크기여야 한다. | E16: 16sp 이상 | F16: UI 점검 | G16: SFR-002 | H16: 진아 | I16: 확정
A17: QUR-008 | B17: 운영 | C17: 수집 실패 모니터링 | D17: 공공 데이터 수집이 연속으로 실패하면 시스템은 에러 로그를 남기고 관리자 알림(SFR-100)을 추가해야 한다. | E17: 연속 3회 실패 시 알림 1건 | F17: API 차단 테스트 | G17: SFR-023, 100 | H17: 백강욱 | I17: 확정 | J17: [v0.96 수정] 알림 수단 D-23
A18: SER-001 | B18: 보안 | C18: 외부 API 키 서버 보관 | D18: 외부 서비스 인증 키는 앱에 포함하지 않고 서버에서만 사용해야 한다. (단말 내장 지도 SDK 키는 해당 SDK 규정을 따른다) | E18: 앱 번들 내 서버 키 0개 | F18: 번들 검사 | G18: SFR-023 | H18: 백강욱 | I18: 확정
A19: SER-002 | B19: 개인정보 | C19: 위치 기록 익명화 | D19: 이동 종료(도착·취소) 후 원본 위치 기록은 대원 계정·팀·이송 건 연결을 끊은 익명 이송 경로(DAR-014)로 즉시 바꿔야 한다. 익명 이송 경로는 관리자만 볼 수 있고, 열람은 작업 이력(SFR-091)에 남긴다. | E19: 종료 후 계정·팀·이송 건과 연결된 위치 기록 0건 | F19: DB 조회 확인 | G19: SFR-041 | H19: 백강욱 | I19: 확정 | J19: 결정 D-06, C-01 / [v1.4 수정] 즉시 삭제 → 익명화 후 축적 (CR-004, D-113)
A20: SER-003 | B20: 개인정보 | C20: 소요시간 익명 보관 | D20: 소요시간 데이터는 대원 계정과 연결하지 않고 보관해야 한다. | E20: 계정 식별 정보 0건 | F20: 데이터 검토 | G20: SFR-039 | H20: 백강욱 | I20: 확정 | J20: 결정 C-01
A21: SER-004 | B21: 보안 | C21: 비밀번호·라이선스 키 변환 저장 | D21: 비밀번호와 병원 라이선스 키는 복호화할 수 없는 방식으로 변환해 저장해야 한다. 관리 화면에 보여줄 라이선스 키 앞 4자리만 따로 저장한다. | E21: 평문 저장 0건 | F21: DB 조회 확인 | G21: SFR-018, 116, 123 | H21: 백강욱 | I21: 확정 | J21: 팀 확인 필요 / [v0.107 수정] 라이선스 키 추가 (D-70)
A22: SER-005 | B22: 법적고지 | C22: 서비스 면책 고지 | D22: 시스템은 첫 실행 화면과 설정 메뉴에 '본 서비스는 참고용이며 의료 판단과 병원 수용을 보장하지 않습니다'를 고지해야 한다. | E22: 고지 화면 존재 | F22: 화면 점검 | G22: SFR-081, 096 | H22: 백강욱 | I22: 확정
A23: SER-006 | B23: 보안 | C23: 비밀번호 규칙 | D23: 비밀번호는 목표값 규칙을 만족해야 한다. | E23: 8자 이상, 영문+숫자 | F23: 가입 테스트 | G23: SFR-018 | H23: 백강욱 | I23: 확정
A24: SER-007 | B24: 보안 | C24: 로그인 유지 기간 (근무 단위) | D24: 로그인 세션은 근무 종료(직접·자동) 때 즉시 끝나야 하며, 목표값을 넘겨 유지되지 않아야 한다. 근무 종료 때 서버의 갱신 토큰을 폐기한다. | E24: 근무 시작 후 14시간 (진행 중 이송이 있으면 그 이송이 끝난 뒤, SFR-113) | F24: 세션 테스트 | G24: SFR-018 | H24: 백강욱 | I24: 확정 | J24: [v1.4 수정] 30일 → 근무 단위 (CR-004, D-110) / [v1.4.1 수정] 이송 중 14시간 경과 시 끝난 뒤 종료 (CR-005)
A25: SER-008 | B25: 보안 | C25: 통신 암호화 | D25: 앱·병원 웹·관리자 웹·서버 사이의 모든 통신은 암호화되어야 한다. | E25: 평문 전송 0건 | F25: 통신 점검 | G25: 전체 | H25: 백강욱 | I25: 확정 | J25: [v0.92 신규] 위치정보 전송 보호 / [v0.100 수정] 병원 웹 추가
A26: SER-009 | B26: 보안 | C26: 요청 인증 | D26: 기록·관리·이송 요청·병원 응답 요청은 인증된 요청(대원·관리자: 로그인 세션, 병원 웹: 등록 PC 토큰 COR-012)만 처리하고, 인증되지 않은 요청은 거부해야 한다. | E26: 미인증 요청 처리 0건 | F26: 미인증 요청 테스트 | G26: SFR-034, 037, 126, 082, 109, 116, 119 | H26: 백강욱 | I26: 확정 | J26: [v0.92 신규] / [v0.98 수정] 이송 요청·병원 응답 포함 / [v0.107 수정] 병원 PC 토큰 인증 (D-70)
A27: SER-010 | B27: 보안 | C27: 권한별 접근 제어 | D27: 시스템은 권한별로 기능을 제한해야 한다. ① 승인 대기: '승인 대기 중' 화면만 ② 구급대원: ①+이송 요청·팀·이송·전화 결과 기록 ③ 병원 담당자: 라이선스 키로 등록한 PC의 병원 웹(자기 병원 대상 요청만) ④ 관리자: 관리자 웹 전체(통계는 관리자만) ⑤ 정지된 대원: 로그인 불가 | E27: 권한 밖 기능 접근 0건 | F27: 권한별 시나리오 테스트 | G27: SFR-022, 082, 116 | H27: 백강욱 | I27: 확정 | J27: [v0.92 신규] / [v0.98 수정] 병원 담당자 권한 추가 / [v0.107 수정] 병원 PC 등록·정지 계정 반영 (D-70, D-75) / [v0.109 수정] 승인 대기 화면 단순화 (D-95)
A28: SER-011 | B28: 보안 | C28: 로그인 실패 제한 | D28: 대원 앱 로그인, 관리자 웹 로그인(OTP 포함), 병원 웹 라이선스 키 입력은 연속으로 실패하면 목표값만큼 잠가야 한다. | E28: 5회 실패 시 10분 잠금 | F28: 로그인 테스트 | G28: SFR-018, 082, 116, 152 | H28: 백강욱 | I28: 확정 | J28: [v0.92 신규] 관리자 계정 보호 / [v0.102 수정] 병원 웹 포함 (D-54) / [v0.107 수정] 병원은 라이선스 키 입력 기준, 앱 PIN·OTP 추가 (D-70, D-74, D-75) / [v1.4 수정] 앱 PIN 삭제 (D-110) / [v1.4.2 수정] 삭제된 SFR-150 참조 제거 (CR-006)
A29: SER-012 | B29: 개인정보 | C29: 환자 식별 정보 미수집 | D29: 시스템은 환자 이름·주민등록번호·연락처 등 환자를 식별할 수 있는 정보를 입력받거나 저장하지 않아야 한다. 단, 구급활동일지 초안(SFR-164)에서 대원이 단말에 직접 입력하는 칸은 예외로 하며, 그 값은 서버로 보내거나 저장하지 않는다(DAR-015). | E29: 서버 저장 필드 0개 · 서버 전송 0건 (일지 초안 단말 입력란은 예외) | F29: 화면·DB 점검 | G29: SFR-108 | H29: 백강욱 | I29: 확정 | J29: [v0.98 신규] 9/29 회의 / [v0.99 수정] 성별·추정 나이대는 식별 정보가 아님 (D-40) / [v1.4.1 수정] 일지 초안 단말 입력란 예외 (CR-005, D-124)
A30: SER-013 | B30: 보안 | C30: 병원별 요청 열람 제한 | D30: 병원 계정은 자기 병원에 보낸 이송 요청만 조회·응답할 수 있어야 한다. | E30: 다른 병원 요청 열람 0건 | F30: 권한 테스트 | G30: SFR-116, 118 | H30: 백강욱 | I30: 확정 | J30: [v0.98 신규]
A31: SER-014 | B31: 개인정보 | C31: 닫힌 요청 환자 정보 열람 차단 | D31: 병원 웹에서 요청이 닫히면(다른 병원 확정·거절·만료·승인 해제·승인 취소·목적지 변경으로 빠짐·수용 불가·이송 취소) 그 병원은 해당 요청의 환자 평가 정보를 볼 수 없어야 하며, 요청 시각과 결과만 표시한다. 실제로 환자를 받는 병원(확정 병원)만 도착 처리 후 1시간(초안)까지 열람할 수 있다. | E31: 닫힌 요청의 환자 정보 조회 성공 0건 | F31: 권한 테스트(병원 웹 화면·API 직접 호출) | G31: SFR-118, 125, 127, 077, 128, 158 | H31: 백강욱 | I31: 확정 | J31: [v0.101 신규] 결정 D-56 / [v0.107 수정] 닫히는 경우 추가 (D-77) / [v0.110 수정] 확정 병원 열람 끝 시점 (D-96)
A32: DAR-001 | B32: 데이터 | C32: 진료가능 항목→필수 병상 매핑표 | D32: 진료가능 항목마다 반드시 필요한 병상 종류(응급실/중환자실/수술실)를 정의한 표를 관리해야 한다. | E32: 10_부록 C 전 항목 | F32: PM 확정표 기준 테스트 (의료 검증은 향후) | G32: SFR-030 | H32: 백강욱 | I32: 확정 | J32: [v0.96 수정] 초안 작성(10_부록 C), 의료 검증 전 — D-21 / [v0.102 수정] PM 초안으로 확정 (D-21) / [v0.103 수정] 이름 통일 (오류 25)
A33: DAR-002 | B33: 데이터 | C33: 증상·부위→태그 매핑표 | D33: 대원이 고르는 증상 선택지가 어떤 진료가능 항목에 해당하는지 정의한 표를 관리해야 한다. | E33: 10_부록 B 선택지 16개 | F33: PM 확정표 기준 테스트 (의료 검증은 향후) | G33: SFR-003 | H33: 백강욱 | I33: 확정 | J33: [v0.96 수정] 초안 작성(10_부록 B), 의료 검증 전 — D-21 / [v0.102 수정] PM 초안으로 확정 (D-21)
A34: DAR-003 | B34: 데이터 | C34: 계정 정보 보관 | D34: 계정·프로필은 탈퇴 즉시 삭제하고, 반려된 가입 신청은 반려일로부터 목표값 후 삭제해야 한다. | E34: 반려 신청 30일 | F34: 삭제 배치 확인 | G34: SFR-071, 083 | H34: 승언 | I34: 확정 | J34: [v0.92 신규] / [v1.3 담당] 확인 담당 백강욱 → 승언 (D-109: 자동 파기 배치)
A35: DAR-004 | B35: 데이터 | C35: 전화 결과·거절 기록 보관 | D35: 전화 결과·거절 기록은 대원 계정과 연결하지 않고 목표값 동안 보관해야 한다. | E35: 1년 | F35: 데이터 검토 | G35: SFR-034, 126 | H35: 백강욱 | I35: 확정 | J35: [v0.92 신규] 결정 C-11
... A61: QUR-014 | B61: 운영 | C61: 일 단위 정합성 점검 | D61: 시스템은 매일 1번 데이터 정합성을 점검해야 한다: ① 마지막 활동 후 2시간이 지났는데 진행 중인 이송 건 ② 확정됐는데 다른 병원 요청이 닫히지 않은 건 ③ 보내지 못한 이벤트(outbox) ④ 계정과 연결된 채 남은 위치 기록. 발견하면 관리자 알림 목록(SFR-100)에 올린다. | E61: 매일 1회, 발견 0건 목표 | F61: 일부러 어긋난 데이터를 넣고 점검 확인 | G61: SFR-086, 100, SER-002 | H61: 백강욱 | I61: 확정 | J61: [v1.4 신규] 배민 일 단위 대사 작업 참고 (CR-004, D-122)

Sheet 05_제약사항
A1: 5.1 제약사항
A2: ID | B2: 분류 | C2: 제약명 | D2: 내용 | E2: 상태 | F2: 비고
A3: COR-001 | B3: 일정 | C3: 개발 기간 | D3: 개발 기간은 8주(1주 스프린트 8회)이다. S8은 통합·부하 테스트, 버그 수정, 시연 리허설 주간이다. | E3: 확정
A4: COR-002 | B4: 기술 | C4: 앱 개발 스택 | D4: 구급대원 앱은 React Native로 개발하며, Android와 iOS를 같은 코드로 빌드한다. | E4: 확정 | F4: [v0.99 수정] 카카오 내비 SDK는 React Native 공식 지원이 없어 네이티브 모듈로 연결 (D-26) / [v0.111 수정] Android·iOS 같은 코드, 네이티브 모듈은 OS마다 연결 (D-97)
A5: COR-003 | B5: 기술 | C5: 지도·경로 안내 수단 | D5: 자체 지도를 구현하지 않는다. 앱 안 경로 안내는 카카오 내비 SDK를 OS마다(Android·iOS) 네이티브 모듈로 연결해 쓰고, 그 OS의 S1 검증에서 불가하면 그 OS는 카카오내비 앱 호출로 바꾼다. iOS 연결은 Android 연결 뒤에 붙이며, 그 전까지 iOS는 카카오내비 앱 호출로 충족한다(D-97). 예상 이동시간은 서버에서 카카오 길찾기 API로 산출한다. 경로 안내는 앱 안 안내 또는 카카오내비 앱으로 목적지 전달 중 하나면 충족한다(SFR-031, D-91). 지도 표시(예비 추천 지도·승인 병원 지도·관리자 응급실 입구 좌표 지정)는 카카오 지도 SDK(앱: React Native 연결, 웹: JavaScript)를 쓰고 S1 검증 스파이크에 포함한다. | E5: 확정 | F5: 결정 D-07, D-26 / [v0.99 수정] TMAP → 카카오 / [v0.108 수정] D-91 / [v0.110 수정] 지도 SDK (D-96) / [v0.111 수정] iOS 내비 연결 순서 (D-97)
A6: COR-004 | B6: 운영 | C6: 개발·시연·운영 환경 분리 | D6: 개발·테스트 환경, 시연 환경, 운영 환경의 서버·데이터를 서로 분리한다. 시연 환경 데이터는 운영 데이터·통계와 섞이지 않는다. | E6: 확정 | F6: [v0.92 신규] 테스트 중 운영 데이터 훼손 방지 / [v0.103 수정] 시연 환경을 운영과 분리 (오류 2) / [v1.4.2] 초안 → 확정 (CR-006)
A7: COR-007 | B7: 범위 | C7: 소속기관 코드·관리자 계정 등록 | D7: 소속기관 코드 목록(소방서 단위)과 관리자 계정은 초기 데이터로 등록하며, 이를 관리하는 화면과 관리자 가입 메뉴는 이번 범위에서 만들지 않는다. 시연용 대원 계정(이름·소방서·계급·안전센터·사번)도 초기 데이터로 넣는다. | E7: 확정 | F7: [v0.96 신규] SFR-017 '등록된 코드'의 출처, 검토 지적 반영 / [v0.107 수정] 관리자 가입 메뉴 없음 명시 (D-75) / [v0.108 수정] 목록 초대가 S5로 이동 (D-85) / [v1.4.2] 초안 → 확정 (CR-006)
A8: COR-006 | B8: 기술 | C8: 지원 플랫폼 | D8: 구급대원 앱은 Android 10 이상 스마트폰과 iOS 16 이상 iPhone(초안)을 지원한다. 화면과 기능은 같고, OS 차이(위치 기록 표시·권한·생체 인증·푸시·무음 모드)는 COR-014를 따른다. | E8: 확정 | F8: [v0.96 신규] 결정 D-22 / [v0.111 수정] iOS 지원 (D-97, D-22 번복)
A9: COR-005 | B9: 구조 | C9: 구급대원 서비스 전용 백엔드 | D9: 백엔드·DB는 구급대원 앱·병원 웹·관리자 웹 전용으로 개발하며, 일반인 앱과 공유하지 않는다. | E9: 확정 | F9: [v0.98 수정] 결정 D-35 (일반인 팀은 별도 진행)
A10: COR-009 | B10: 기술 | C10: 대원 푸시 알림 수단 | D10: 앱이 백그라운드일 때 대원 알림(SFR-130)은 Firebase Cloud Messaging(FCM)으로 보낸다. iOS는 FCM이 Apple 푸시(APNs)로 전달하며, APNs 인증 키를 Firebase에 등록한다. 푸시는 서버가 Firebase에 요청해 보내며 별도 푸시 서버는 두지 않는다. 앱이 화면에 켜져 있으면 실시간 연결로, 백그라운드·종료 상태면 FCM으로 알린다. | E10: 확정 | F10: [v0.100 신규] 결정 D-51 / [v0.111 수정] iOS는 APNs 경유 (D-97) / [v1.4 수정] 푸시 구조 명시 (D-119) / [v1.4.2] 초안 → 확정 (CR-006)
A11: COR-008 | B11: 구조 | C11: 병원 웹·관리자 웹 구성 | D11: 병원 웹은 관리자 웹과 같은 웹 프로젝트(Next.js)에서 권한으로 화면을 나눠(/hospital, /admin) 개발하고, 요청 알림은 서버와의 실시간 연결로 받는다. 브라우저 정책상 근무 시작 때 '알림 켜기'를 한 번 눌러야 소리가 난다. 병원 웹은 웹 브라우저로만 제공하며, 설치형 PC 프로그램과 설치형 웹앱(PWA)은 이번 범위에서 만들지 않는다. 병원 PC 안내서에 '브라우저 설정에서 병원 웹을 항상 활성 상태로 유지할 사이트로 등록'을 넣는다(탭 절전 방지, SFR-161). 배포는 관리자 화면만 별도 서버로 분리한다(COR-016). | E11: 확정 | F11: [v0.98 신규] 결정 D-27 / [v0.107 수정] 웹만 (D-72) / [v0.108 수정] 탭 절전 방지 안내 (D-93) / [v1.4 수정] 관리자 분리 배포 (D-117) / [v1.4.2] 초안 → 확정 (CR-006)
A12: COR-010 | B12: 운영 | C12: 시연 환경 구성 | D12: 시연은 앱 기능이 아닌 환경 구성으로 한다. ① 시연 서버는 공공 API 대신 준비한 고정 병상 데이터를 읽는다 ② 위치 이동은 Android 에뮬레이터·iOS 시뮬레이터 경로 재생 또는 단말의 모의 위치로 한다 ③ 병원 응답은 가짜 병원 계정 여러 개로 팀원이 병원 웹에서 직접 조작한다 ④ 환자 정보는 가상 데이터만 쓴다. ⑤ 병원 웹은 병원마다 브라우저 프로필을 따로 만들어 띄운다(PC 등록 쿠키가 프로필마다 따로 저장됨). | E12: 확정 | F12: [v0.103 신규] 모의 모드 삭제 대체 (D-60) / [v0.108 수정] 시연 준비 (검토) / [v0.111 수정] iOS 시뮬레이터 (D-97)
A13: COR-011 | B13: 범위 | C13: 대상 구급차 | D13: 이번 범위는 119 구급대만 대상으로 한다. 사설(민간) 구급차는 가입·인증 체계와 법적 지위가 달라 향후 과제로 둔다. | E13: 확정 | F13: [v0.107 신규] 결정 D-69 (9/30 회의)
A14: COR-012 | B14: 기술 | C14: 병원 PC 등록 방식 | D14: 라이선스 키가 맞으면 서버는 PC 등록 토큰을 발급해 브라우저의 httpOnly 쿠키에 저장하고, 병원 웹 요청마다 이 토큰으로 병원을 확인한다. 쿠키가 지워지면 키를 다시 입력하고 기존 PC를 교체한다(SFR-116). | E14: 확정 | F14: [v0.107 신규] 결정 D-70 / [v1.4.2] 초안 → 확정 (CR-006)
A15: COR-013 | B15: 운영 | C15: 라이선스 키 전달 | D15: 관리자는 라이선스 키를 이메일·문자로 보내지 않고, 병원 대표번호로 전화해 응급실 책임자를 확인한 뒤 말로 전달한다. 키는 응급실 책임자가 보관한다. | E15: 확정 | F15: [v0.107 신규] 결정 D-70 / [v1.4.2] 초안 → 확정 (CR-006)
... A18: COR-016 | B18: 운영 | C18: 운영 서버 구성 | D18: 운영 환경은 앱 서버 2대 + 로드밸런서 + 데이터 서버 1대(DB·공유 저장소) + 객체 저장소로 구성한다. 앱 서버끼리 공유할 상태(실시간 연결·타이머·요청 제한·호출 수)는 서버 메모리에 두지 않고 공유 저장소나 DB에 둔다. 주기 작업은 서버 수와 상관없이 한 번만 실행되게 한다. 배포는 앱 서버를 1대씩 차례로 교체한다. DB 복제는 범위 밖이며 매일 백업(QUR-010)으로 대신한다. 상태 점검은 서버 밖 외부 서비스로 한다. 관리자 웹은 로드밸런서 뒤 앱 서버와 따로 관리자 전용 서버 1대에서 운영하고 접속 IP를 제한하며, 같은 DB·공유 저장소를 쓴다(대원 정지 시 즉시 차단, SER-016). 구급대원·병원 기능은 같은 이송 건을 함께 바꾸므로 한 백엔드에 둔다. | E18: 확정 | F18: [v1.2 신규] 전국 운영 규모와 서버 1대 장애 시 전국 중단 문제 (CR-002, D-105·106) / [v1.4 수정] 관리자 웹 독립 서버, 구급대원·병원 서버는 분리하지 않음 (CR-004, D-117·118)
A20: 5.2 가정 및 의존성
A21: ID | B21: 구분 | C21: 내용 | D21: 영향 / 비고
A22: ASM-01 | B22: 가정 | C22: 공공 병상 데이터는 실시간이 아니며 갱신 시차가 있다. | D22: 시차 때문에 '참고용' 표시와 전화 확인이 필요 (SFR-032, 081)
A23: ASM-02 | B23: 가정 | C23: 구급차 운행 구간에는 통신 두절 지역(산간·터널·지하)이 존재한다. | D23: 오프라인 대응(03 탭 '오프라인' 분류)과 통신 두절 시 바로 예비 흐름(SFR-109)의 근거
A24: ASM-03 | B24: 가정 | C24: 음성 통화는 데이터 통신과 별개로 동작한다. | D24: 오프라인 전화 활성(SFR-061)의 근거
A25: ASM-04 | B25: 의존 | C25: 카카오 내비 SDK를 Android·iOS 각각 React Native 네이티브 모듈로 연결할 수 있어야 한다. | D25: OS별 S1 검증 스파이크로 확인, 불가 시 그 OS는 카카오내비 앱 호출로 전환 (D-26, D-97)
A26: ASM-05 | B26: 의존 | C26: 공공 데이터 일일 호출 한도(개발계정 10,000회) 안에서 운영 환경은 전국 17개 시·도를 3분 주기로 수집한다 (하루 약 8,160회, 한도의 약 82%). 시연 환경은 고정 데이터를 쓰고(COR-010), 개발 환경은 개발용 키로 수집 대상을 줄여 테스트한다. | D26: 개발·운영 키를 분리하고 한도 증량(활용사례 등록)을 함께 신청 / 하루 호출 수 감시: 80% 알림·100% 수집 중단 (SFR-090) / 실시간 병상 값이 없는 병원은 '병상 정보 없음'으로 따로 표시 (D-89) / [v1.2 수정] 시·도 1곳 → 전국 (CR-002, D-104, D-59 번복)
A27: ASM-08 | B27: 가정 | C27: 병원 응급실에는 병원 웹을 켜 둔 PC가 근무 시간 내내 있다. | D27: 알람 수신의 전제 (SFR-117, 122) / 병원 웹은 PC 화면 기준, 태블릿·폰 화면은 이번 범위 아님 (D-58)
A28: ASM-09 | B28: 가정 | C28: 시연에서는 팀원이 가짜 병원 계정 여러 개로 병원 웹을 직접 조작한다. | D28: 실제 병원 참여 없이 시연 (COR-010)
A29: ASM-07 | B29: 가정 | C29: 중증질환 항목·병상 필드 이름은 공개 활용 코드 기준으로 정리했다. | D29: 공식 API 명세서(V13)로 최종 확인 필요 (10_부록 C·D)
A30: ASM-06 | B30: 의존 | C30: 개발 생산성 확보를 위해 AI 개발 도구를 활용한다. | D30: Must 범위 설정의 근거 (01_개요 참고)
A31: ASM-10 | B31: 가정 | C31: 구급대원 앱은 대원 개인 스마트폰(Android·iPhone)에서만 쓰며, 여러 대원이 함께 쓰는 공용·업무용 단말은 대상이 아니다. | D31: D-57 / [v1.4.1 수정] 개인 폰만 (D-124, D-57 번복)
A32: ASM-11 | B32: 가정 | C32: 팀이 테스트용 iPhone 1대 이상을 확보한다. (iOS 빌드용 맥은 보유 확인) | D32: iOS 실기기 테스트·시연의 전제 (COR-015, D-97)
A33: ASM-12 | B33: 의존 | C33: 길찾기 서비스는 무료 사용량(하루 자동차 길찾기 1만 건·다중 목적지 1천 건·내비 SDK 10만 건) 안에서 운영한다. 요청 때 10km 밖은 추정값, 이동 중은 내비 SDK 값을 써서 서버 호출을 줄인다(SFR-121·129). | D33: 전국 실제 운영은 유료 전환이나 제휴가 필요 / [v1.2 신규] (CR-002, D-106)

Sheet 06_유스케이스
A1: UC-01 병원 승인 후 이송
A2: 구분 | B2: 단계 | C2: 내용 | D2: 관련 요구사항
A3: 액터 | C3: 주 액터: 구급대원(같은 팀 대원 포함) / 보조 액터: 병원 응급실 담당자(병원 웹), 경로 안내 서비스
A4: 목표 | C4: 현장에서 환자 정보를 입력해 반경 안 병원에 한 번에 요청하고, 승인한 병원 중 한 곳으로 이송해 도착까지 기록한다.
A5: 사전조건 | C5: ① 대원 계정 승인 완료 ② 위치정보 수집 동의 ③ 근무 시작 때 팀을 맺은 상태 ④ 반경 안 병원 담당자가 라이선스 키로 등록된 PC에서 병원 웹을 열고 '알림 켜기'를 누른 상태 | D5: SFR-017, 083, 113, 116, 117
A6: 트리거 | C6: 대원이 현장에서 앱을 실행한다.
A7: 기본흐름 | B7: 1 | C7: 시스템은 환자 정보 입력 화면을 첫 화면으로 표시하고, 반경 안 병원 목록을 미리 불러온다. | D7: SFR-107, 001
A8: 기본흐름 | B8: 2 | C8: 대원(또는 같은 팀 대원)이 주 증상·의식 수준·활력징후·통증·외상 여부 등 필수 항목을 입력한다. | D8: SFR-108, 114
